Workbook
Name Cover_Price: Cover!$C$9
Name Cover_Shares: Cover!$C$11
Name Cover_MktCap: Cover!$C$12
Name Cover_Debt: Cover!$C$13
Name Cover_Cash: Cover!$C$14

Sheet Cover
B2: ADOBE INC.
B3: NASDAQ: ADBE — 3-Statement Model, Freemium-Funnel Driver Model & DCF
B4: Educational / illustrative model built from public filings — NOT investment advice
B5: Model date: | C5: 2026-08-29
B6: Fiscal year end: | C6: Fri nearest 30 Nov (FY2025 ended 28 Nov 2025) | F6: FY2026 in progress; Q2 FY26 (ended 29 May 2026) is the last reported quarter. Q3 FY26 reports 10 Sep 2026 and is NOT in this model.
A8: MARKET SNAPSHOT — each figure carries its own observation date
B9: Share price | C9: 291.52 | F9: Yahoo Finance, close 28 Aug 2026 20:00 UTC
B10: 52-week high / low (intraday) | C10: $370.86 / $190.12 | F10: Yahoo Finance, 28 Aug 2026. Closing basis: $367.46 (18 Sep 2025) / $193.41 (25 Jun 2026)
B11: Shares outstanding (mm) | C11: 397.5 | F11: stockanalysis.com, 28 Aug 2026. XBRL CommonStockSharesOutstanding was 399.0mm at 29 May 2026
B12: Market capitalization ($mm) | C12: =Cover_Price*Cover_Shares | F12: Formula: price x shares outstanding
B13: Total debt ($mm) | C13: 6645 | F13: 10-Q 29 May 2026: $1,843mm current + $4,802mm long-term
B14: Cash + short-term investments ($mm) | C14: 5626 | F14: 10-Q 29 May 2026: $4,919mm cash + $707mm STI
B15: Net cash / (net debt) ($mm) | C15: =C14-C13 | F15: Formula: cash - debt. Adobe is modestly NET DEBT after the Semrush deal
B16: Enterprise value ($mm) | C16: =C12+C13-C14 | F16: Formula: market cap + debt - cash. Cross-check: stockanalysis.com $117,330mm
B17: Beta (5-year) | C17: 1.4 | F17: stockanalysis.com, 28 Aug 2026. Methodologies differ by provider — cross-check before relying on WACC
B18: Short interest (mm sh / % float) | C18: 17.97mm / 4.54% | F18: stockanalysis.com, 28 Aug 2026 (settlement date lags ~2 weeks)
A20: VALUATION SUMMARY (live — pulls from the Scenarios tab)
B21: Bear case target | C21: =Scenarios!C37 | D21: =IFERROR(C21/Cover_Price-1,"n/m") | E21: vs. price
B22: Base case target | C22: =Scenarios!D37 | D22: =IFERROR(C22/Cover_Price-1,"n/m") | E22: vs. price | F22: The Base case is NOT a house view that the stock is worth this: it is what Adobe's own guided FY2026 numbers, extended at a decelerating growth rate with a modest margin fade, are worth at a CAPM discount rate. The gap to the $291.52 price is the market's AI-disruption discount, and the reverse DCF on the DCF & WACC tab measures it directly.
B23: Bull case target | C23: =Scenarios!E37 | D23: =IFERROR(C23/Cover_Price-1,"n/m") | E23: vs. price
B24: Blended target (avg of DCF & exit-multiple, Base) | C24: =Scenarios!D37
B25: Probability-weighted target (30% / 50% / 20%) | C25: =Scenarios!C40
B26: Upside / (downside) to probability-weighted target | C26: =Scenarios!C41
B27: Sell-side consensus target (40 analysts, 19 Aug 2026) | C27: 270.61 | F27: S&P Global consensus via stockanalysis.com: 'Hold', mean $270.61, MEDIAN $250.00, range $190-$380. The stock closed 28 Aug 2026 ABOVE the mean target — the sell side has not caught up to the rally.
A29: WHAT THIS MODEL IS AND ISN'T
B30: A full 3-statement model (income statement, fully itemised balance sheet, cash flow) with a five-year explicit forecast feeding a DCF, plus a dedicated freemium-funnel driver model. Adobe genuinely needs the full build rather than one sensitivity grid: its value depends on the INTERACTION of (a) ARR growth, which management deliberately traded away in H2 FY26 to buy monthly active users, (b) gross margin, which is under real pressure from generative-AI inference cost sitting in subscription COGS, and (c) an ~$9bn/yr buyback that is retiring ~7% of the share count a year and is the single largest contributor to EPS growth. None of those three can be read off the others. Every yellow cell is an editable assumption, not a prediction. The specific uncertainties: whether a ~90mm creative-freemium MAU base converts to paid at a rate that replaces the deferred direct-to-paid ARR; whether Firefly/Acrobat AI pricing holds as OpenAI, Google and Canva give away adjacent capability; and who Adobe's next CEO is (search ongoing since Mar 2026).
B31: Tabs: Quarterly Financials | ARR & Freemium Driver | Income Statement | Balance Sheet | Cash Flow & Working Capital | DCF & WACC | Scenarios | Sensitivity | Comps | Technicals | Catalysts | Sources & Assumptions
B33: DISCLAIMER
B34: Not investment, legal or tax advice. Built from public secondary sources and SEC filings at a point in time, not a live market-data terminal. Verify every decision-critical figure against primary sources.

Sheet Quarterly Financials
A2: QUARTERLY TREND — $mm (the deceleration/reacceleration story lives here)
B3: All figures from SEC filings: 10-Q income statements (EDGAR XBRL) and Adobe 8-K Ex-99.1 earnings releases. Q4 FY25 is DERIVED (FY2025 10-K total less Q1-Q3 10-Q figures) because Adobe does not tag a discrete Q4 in XBRL; the derived revenue of $6,194mm ties to the $6.19bn reported in the Q4 FY25 release. Q3 FY26 columns are GUIDANCE midpoints, not actuals.
B5: Quarter ended | C5: Q1 FY25 | D5: Q2 FY25 | E5: Q3 FY25 | F5: Q4 FY25 | G5: Q1 FY26 | H5: Q2 FY26 | I5: Q3 FY26G
B6: Period end date | C6: 2025-02-28 | D6: 2025-05-30 | E6: 2025-08-29 | F6: 2025-11-28 | G6: 2026-02-27 | H6: 2026-05-29 | I6: 2026-08-28E
B7: Total revenue | C7: 5714 | D7: 5873 | E7: 5988 | F7: 6194 | G7: 6398 | H7: 6618 | I7: 6695
B8: Revenue growth YoY | G8: =IF(ISBLANK(G7),"n/a",IFERROR(G7/C7-1,"n/a")) | H8: =IF(ISBLANK(H7),"n/a",IFERROR(H7/D7-1,"n/a")) | I8: =IF(ISBLANK(I7),"n/a",IFERROR(I7/E7-1,"n/a"))
B9: Total cost of revenue | C9: 622 | D9: 638 | E9: 642 | F9: 649 | G9: 664 | H9: 715
B10: Gross profit | C10: =IF(ISBLANK(C9),"n/a",C7-C9) | D10: =IF(ISBLANK(D9),"n/a",D7-D9) | E10: =IF(ISBLANK(E9),"n/a",E7-E9) | F10: =IF(ISBLANK(F9),"n/a",F7-F9) | G10: =IF(ISBLANK(G9),"n/a",G7-G9) | H10: =IF(ISBLANK(H9),"n/a",H7-H9) | I10: =IF(ISBLANK(I9),"n/a",I7-I9)
B11: Gross margin % | C11: =IF(ISBLANK(C9),"n/a",IFERROR((C7-C9)/C7,"n/a")) | D11: =IF(ISBLANK(D9),"n/a",IFERROR((D7-D9)/D7,"n/a")) | E11: =IF(ISBLANK(E9),"n/a",IFERROR((E7-E9)/E7,"n/a")) | F11: =IF(ISBLANK(F9),"n/a",IFERROR((F7-F9)/F7,"n/a")) | G11: =IF(ISBLANK(G9),"n/a",IFERROR((G7-G9)/G7,"n/a")) | H11: =IF(ISBLANK(H9),"n/a",IFERROR((H7-H9)/H7,"n/a")) | I11: =IF(ISBLANK(I9),"n/a",IFERROR((I7-I9)/I7,"n/a"))
B12: Research & development | C12: 1026 | D12: 1082 | E12: 1088 | F12: 945 | G12: 1110 | H12: 1198
B13: Sales & marketing | C13: 1495 | D13: 1626 | E13: 1639 | F13: 1728 | G13: 1708 | H13: 1884
B14: General & administrative | C14: 367 | D14: 377 | E14: 408 | F14: 421 | G14: 463 | H14: 546
B15: Amortization of intangibles | C15: 41 | D15: 41 | E15: 38 | F15: 190 | G15: 35 | H15: 37
B16: Total operating expenses | C16: 2929 | D16: 3126 | E16: 3173 | F16: 3284 | G16: 3316 | H16: 3665
B17: GAAP operating income | C17: 2163 | D17: 2109 | E17: 2173 | F17: 2261 | G17: 2418 | H17: 2238
B18: GAAP operating margin % | C18: =IF(ISBLANK(C17),"n/a",IFERROR(C17/C7,"n/a")) | D18: =IF(ISBLANK(D17),"n/a",IFERROR(D17/D7,"n/a")) | E18: =IF(ISBLANK(E17),"n/a",IFERROR(E17/E7,"n/a")) | F18: =IF(ISBLANK(F17),"n/a",IFERROR(F17/F7,"n/a")) | G18: =IF(ISBLANK(G17),"n/a",IFERROR(G17/G7,"n/a")) | H18: =IF(ISBLANK(H17),"n/a",IFERROR(H17/H7,"n/a")) | I18: =IF(ISBLANK(I17),"n/a",IFERROR(I17/I7,"n/a"))
B19: GAAP net income | C19: 1811 | D19: 1691 | E19: 1772 | F19: 1856 | G19: 1889 | H19: 1712
B20: GAAP diluted EPS | C20: 4.14 | D20: 3.94 | E20: 4.18 | F20: 4.45 | G20: 4.6 | H20: 4.25 | I20: 4.425
B21: Non-GAAP diluted EPS | E21: 5.31 | F21: 5.5 | G21: 6.06 | H21: 5.96 | I21: 6.075
B22: Cash flow from operations | C22: 2482 | D22: 2191 | E22: 2198 | F22: 3160 | G22: 2958 | H22: 2165
B23: Stock-based compensation | C23: 475 | D23: 481 | E23: 497 | F23: 489 | G23: 509 | H23: 534
B24: Depreciation, amortization & accretion | C24: 217 | D24: 209 | E24: 208 | F24: 184 | G24: 174 | H24: 193
B25: Capital expenditures | C25: 26 | D25: 47 | E25: 72 | F25: 34 | G25: 37 | H25: 58
B26: Share repurchases ($mm) | C26: 3250 | D26: 3500 | E26: 2057 | F26: 2474 | G26: 2478 | H26: 2111
B27: Shares outstanding, period end (mm) | C27: 435 | D27: 427 | E27: 420 | F27: 413 | G27: 406 | H27: 399
B28: Remaining performance obligations | D28: 19690 | E28: 20440 | F28: 22520 | G28: 22220 | H28: 22270
B30: READING THE TABLE. (1) Revenue growth ACCELERATED through FY26 (Q1 +12.0%, Q2 +12.7% as reported, ~11% constant currency) while GAAP operating margin FELL from 37.8% in Q1 FY26 to 33.8% in Q2 FY26 - the freemium push and the Semrush deal are being paid for out of the operating line. Q2 also carries a $70mm non-cash goodwill impairment on the Publishing & Advertising unit ($0.17/sh). (2) Subscription cost of revenue grew 16.0% YoY in Q2 FY26 ($586mm vs $505mm) against 13.7% subscription revenue growth: generative-AI inference cost is landing in COGS. (3) Q1/Q2 FY25 non-GAAP EPS are left blank rather than estimated - Adobe's Q4 FY25 release reconciles only Q3, Q4 and the full year. (4) Q4 FY25 is derived (FY2025 10-K less the three 10-Qs); derived revenue of $6,194mm ties to the $6.19bn reported in the Q4 FY25 release, and derived operating income of $2,261mm ties to the reported $2.26bn.

Sheet ARR & Freemium Driver
A2: PART A — THE ARR BRIDGE: WHAT MANAGEMENT TRADED AWAY IN H2 FY26
B3: Adobe's valuation turns on one number: total ending Annualised Recurring Revenue growth. On 11 Jun 2026 management raised FY26 revenue and non-GAAP EPS while simultaneously LOWERING second-half ARR growth expectations, because it chose to route Adobe.com traffic into free Firefly / Express / Acrobat journeys instead of direct-to-paid, and deferred previously planned Creative Cloud 'line optimizations' (price and packaging changes). This block sizes that trade explicitly. Sources: Q2 FY26 and Q4 FY25 earnings releases and prepared remarks (Adobe IR, 11 Jun 2026 / 10 Dec 2025).
C5: FY2025A exit | D5: Q1 FY26A exit | E5: Q2 FY26A exit | F5: FY2026 target exit
B6: Total Adobe ending ARR ($mm) | C6: 25200 | D6: 26060 | E6: 27100 | F6: =C6*(1+C12)
B7: ARR growth YoY | C7: 0.115 | E7: 0.125 | I7: FY25 +11.5% and Q2 FY26 +12.5% are disclosed. Q1 FY26 YoY not disclosed under the new reporting basis.
B8: Net-new ARR in period ($mm) | D8: =D6-C6 | E8: =E6-D6
B9: of which Semrush (inorganic) | D9: 0 | E9: 480 | F9: 0 | I9: Semrush closed 28 Apr 2026 (Q2 FY26) for $1.87bn cash and added ~$480mm of ARR on day one.
B10: ORGANIC net-new ARR ($mm) | D10: =D8-D9 | E10: =E8-E9
B12: FY2026 guided total ending ARR growth | C12: 0.102 | I12: Company target, Q2 FY26 release, 11 Jun 2026. Includes Semrush.
A14: THE H2 FY26 ARR DECELERATION, QUANTIFIED
B15: H1 FY26 total net-new ARR ($mm) | C15: =E6-C6
B16: less: Semrush inorganic ARR | C16: =-E9
B17: H1 FY26 ORGANIC net-new ARR ($mm) | C17: =C15+C16
B18: Implied H2 FY26 net-new ARR ($mm) = FY26 target less Q2 exit | C18: =F6-E6 | I18: This is the number the market reacted to. It is not disclosed directly - it is implied by the company's own FY26 ending-ARR target against its reported Q2 exit ARR.
B19: Total Adobe ARR at Q2 FY25 exit ($mm), derived | C19: =E6/(1+E7) | I19: Derived from the disclosed Q2 FY26 exit ARR of $27,100mm and its disclosed +12.5% YoY growth. Adobe did not report a total-company ARR figure for Q2 FY25 under the old segment basis - flagged as DERIVED.
B20: H2 FY25 actual net-new ARR ($mm) | C20: =C6-C19
B21: H2 FY26 implied net-new ARR vs H2 FY25, YoY change | C21: =IFERROR(C18/C20-1,"n/m") | I21: The single most important number on this tab.
B23: So: Adobe added roughly $1.4bn of ORGANIC ARR in H1 FY26, then guided to roughly $0.7bn across the whole of H2 - against roughly $1.1bn of net-new ARR actually added in H2 FY25. That is an implied ~40% YoY DECLINE in half-yearly net-new ARR, disclosed on the same day as a revenue and non-GAAP EPS raise. Revenue is a lagging indicator of ARR (Adobe recognises subscription revenue ratably), so an ARR air-pocket in H2 FY26 shows up in reported revenue mostly in FY2027. The bull case is that this is a deliberate, temporary investment in a much larger funnel; the bear case is that the freemium pivot is a reaction to demand that was going to weaken anyway. Part B sizes what the funnel has to deliver.
A25: PART B — THE FREEMIUM FUNNEL: MAU x PAID CONVERSION x ARPU
B26: Every figure in the DISCLOSED block is from Adobe's Q2 FY26 prepared remarks (11 Jun 2026). Adobe does NOT disclose a freemium-to-paid conversion rate or a freemium ARPU - both are model assumptions and are marked yellow. The implied conversion economics row backs out what today's disclosed Firefly ARR implies, which is the only anchor available.
B27: Creative freemium MAU (mm) - Firefly, Express, Premiere, Photoshop, Lightroom web/mobile | C27: 90 | I27: 'Crossed 90 million, growing over 70% year over year' - Q2 FY26 prepared remarks. Was >50mm a year earlier.
B28: Business Professionals & Consumers MAU (mm) - Acrobat + Express | C28: 850 | I28: 'Surpassed 850 million, growing approximately 20% year over year' - Q2 FY26 prepared remarks. Was >700mm a year earlier.
B29: Firefly ending ARR ($mm) - apps, credit packs, Firefly Enterprise | C29: 300 | I29: 'Approaching $300 million' exiting Q2 FY26; Firefly ARR grew ~50% QUARTER over quarter.
B30: Total AI-first ARR ($mm) | C30: 500 | I30: '3X year over year increase in AI-first ARR to greater than $500 million' - Q2 FY26. ~1.8% of total ARR.
B31: Adobe.com traffic growth YoY | C31: 0.4 | I31: 'Traffic to Adobe.com, which grew over 40% year over year'; C&CP traffic +50%, BP&C traffic +35%.
B33: ASSUMPTION — blended annual ARPU of a converted freemium user ($/yr) | C33: 120 | I33: MODEL ASSUMPTION, not disclosed. Firefly standard is ~$9.99/mo and Firefly Pro ~$29.99/mo list; $120/yr assumes a heavy skew to the entry tier plus promotional pricing. Edit this cell.
B34: Implied paying creative-freemium users today (mm) | C34: =IFERROR(C29/C33,"n/m") | I34: Formula: Firefly ARR in $mm divided by ARPU in $/yr. Units check: 2.5mm users x $120/yr = $300mm.
B35: Implied paid conversion rate on today's creative freemium MAU | C35: =IFERROR(C34/C27,"n/m") | I35: This is the single most useful number on the tab: it says roughly what share of the 90mm creative freemium base is paying anything today, on the stated ARPU assumption.
A37: SENSITIVITY — CREATIVE FREEMIUM ARR ($mm) = MAU x CONVERSION x ARPU
B38: Creative freemium MAU (mm) DOWN / paid conversion rate ACROSS | C38: 0.01 | D38: 0.02 | E38: 0.03 | F38: 0.045 | G38: 0.06 | H38: 0.08
B39: 90 | C39: =$B39*C$38*$C$33 | D39: =$B39*D$38*$C$33 | E39: =$B39*E$38*$C$33 | F39: =$B39*F$38*$C$33 | G39: =$B39*G$38*$C$33 | H39: =$B39*H$38*$C$33
B40: 130 | C40: =$B40*C$38*$C$33 | D40: =$B40*D$38*$C$33 | E40: =$B40*E$38*$C$33 | F40: =$B40*F$38*$C$33 | G40: =$B40*G$38*$C$33 | H40: =$B40*H$38*$C$33
B41: 180 | C41: =$B41*C$38*$C$33 | D41: =$B41*D$38*$C$33 | E41: =$B41*E$38*$C$33 | F41: =$B41*F$38*$C$33 | G41: =$B41*G$38*$C$33 | H41: =$B41*H$38*$C$33
B42: 240 | C42: =$B42*C$38*$C$33 | D42: =$B42*D$38*$C$33 | E42: =$B42*E$38*$C$33 | F42: =$B42*F$38*$C$33 | G42: =$B42*G$38*$C$33 | H42: =$B42*H$38*$C$33
B43: 320 | C43: =$B43*C$38*$C$33 | D43: =$B43*D$38*$C$33 | E43: =$B43*E$38*$C$33 | F43: =$B43*F$38*$C$33 | G43: =$B43*G$38*$C$33 | H43: =$B43*H$38*$C$33
B44: 420 | C44: =$B44*C$38*$C$33 | D44: =$B44*D$38*$C$33 | E44: =$B44*E$38*$C$33 | F44: =$B44*F$38*$C$33 | G44: =$B44*G$38*$C$33 | H44: =$B44*H$38*$C$33
B46: Memo: today's disclosed Firefly ARR | C46: =C29
B47: Memo: annualised ARR Adobe is deferring in H2 FY26 ($mm) | C47: =C20-C18
B48: Creative freemium conversion rate needed on TODAY'S 90mm MAU to replace it | C48: =IFERROR(C47/(C27*C33),"n/m")
B49: HOW TO READ THE GRID. The green band is where the freemium funnel becomes a genuine second revenue engine rather than a rounding error. The gradient runs far more steeply left-to-right than top-to-bottom: CONVERSION dominates MAU. Adobe can triple the funnel to 240mm users and still add less ARR than it would by lifting conversion from ~3% to ~6% on the base it already has. That is the falsifiable core of the bull case - and it is also why 'MAU grew from 50mm to 90mm' is not, on its own, evidence the strategy is working. Watch reported Firefly ARR against MAU each quarter: if Firefly ARR grows more slowly than MAU, conversion is FALLING and the trade is destroying ARR rather than deferring it.

Sheet Income Statement
A2: INCOME STATEMENT — $mm except per-share (fiscal year ends late November)
B3: Grey columns = reported actuals (FY2024 and FY2025 10-K, EDGAR XBRL). Blue/yellow columns = explicit, editable forecast assumptions. FY2026E is NOT a free forecast: it is calibrated to Adobe's own 11 Jun 2026 guidance of $26.50-26.60bn revenue and $17.90-18.00 GAAP EPS, and reproduces both. Every later year is a scenario, not a prediction.
C5: FY2024A | D5: FY2025A | E5: FY2026E | F5: FY2027E | G5: FY2028E | H5: FY2029E | I5: FY2030E
B6: Total revenue | C6: 21505 | D6: 23769 | E6: =D6*(1+E7) | F6: =E6*(1+F7) | G6: =F6*(1+G7) | H6: =G6*(1+H7) | I6: =H6*(1+I7) | K6: FY24 and FY25 per 10-K (EDGAR XBRL tag Revenues). Forecast = prior year x (1 + growth below).
B7: Revenue growth YoY | D7: =D6/C6-1 | E7: 0.117 | F7: 0.09 | G7: 0.085 | H7: 0.08 | I7: 0.075 | K7: FY26E 11.70% reproduces the $26,550mm guidance midpoint exactly (23,769 x 1.1170 = 26,550). FY27E 9.0% lands at $28,940mm vs Street consensus of $28,920mm. Later years fade toward high-single-digit as the installed base matures and freemium mix dilutes ARPU.
B8: Gross margin % | C8: =1-2358/C6 | D8: =1-2551/D6 | E8: 0.89 | F8: 0.886 | G8: 0.883 | H8: 0.881 | I8: 0.879 | K8: FY24/FY25 derived from reported cost of revenue ($2,358mm / $2,551mm). The forecast fade is a deliberate thesis, not drift: in Q2 FY26 subscription cost of revenue grew 16.0% YoY against 13.7% subscription revenue growth, because generative-credit inference is a variable COGS item that a seat licence never was. If Adobe pushes free generation to 90mm+ MAU, this line gets worse before the paid conversion arrives.
B9: Cost of revenue | C9: =C6*(1-C8) | D9: =D6*(1-D8) | E9: =E6*(1-E8) | F9: =F6*(1-F8) | G9: =G6*(1-G8) | H9: =H6*(1-H8) | I9: =I6*(1-I8)
B10: Gross profit | C10: =C6*C8 | D10: =D6*D8 | E10: =E6*E8 | F10: =F6*F8 | G10: =G6*G8 | H10: =H6*H8 | I10: =I6*I8
B11: R&D % of revenue | C11: =3777/C6 | D11: =4141/D6 | E11: 0.176 | F11: 0.176 | G11: 0.175 | H11: 0.174 | I11: 0.173 | K11: FY24/FY25 R&D derived as total operating expenses less S&M, G&A, intangible amortisation and the FY24 $1,000mm Figma termination fee (all EDGAR XBRL). H1 FY26 actual R&D intensity was 17.73%.
B12: Research & development | C12: =C6*C11 | D12: =D6*D11 | E12: =E6*E11 | F12: =F6*F11 | G12: =G6*G11 | H12: =H6*H11 | I12: =I6*I11
B13: S&M % of revenue | C13: =5764/C6 | D13: =6488/D6 | E13: 0.276 | F13: 0.274 | G13: 0.27 | H13: 0.267 | I13: 0.264 | K13: H1 FY26 actual 27.60%. Held elevated through FY26-27 because the freemium land-grab is a customer-acquisition spend, then fades ~30bp/yr as the funnel is expected to become organic.
B14: Sales & marketing | C14: =C6*C13 | D14: =D6*D13 | E14: =E6*E13 | F14: =F6*F13 | G14: =G6*G13 | H14: =H6*H13 | I14: =I6*I13
B15: G&A % of revenue | C15: =1529/C6 | D15: =1573/D6 | E15: 0.078 | F15: 0.07 | G15: 0.068 | H15: 0.066 | I15: 0.065 | K15: H1 FY26 actual 7.75%, elevated versus FY25's 6.62% (legal and settlement costs, including the $150mm DOJ/FTC ROSCA settlement approved Mar 2026, plus Semrush deal costs). Normalises from FY27E.
B16: General & administrative | C16: =C6*C15 | D16: =D6*D15 | E16: =E6*E15 | F16: =F6*F15 | G16: =G6*G15 | H16: =H6*H15 | I16: =I6*I15
B17: Amortization of acquired intangibles | C17: 336 | D17: 310 | E17: 220 | F17: 250 | G17: 220 | H17: 180 | I17: 142 | K17: FY24/FY25 actual. FY26E-FY30E steps up then runs off the $517mm of intangibles recognised on the Semrush acquisition, sized so the intangibles balance it rolls on the Balance Sheet tab amortises to exactly zero by FY2030E rather than going negative.
B18: Acquisition termination fee / goodwill impairment | C18: 1000 | D18: 0 | E18: 70 | F18: 0 | G18: 0 | H18: 0 | I18: 0 | K18: FY24 = the $1,000mm Figma deal termination fee. FY26E = the $70mm non-cash goodwill impairment on the Publishing & Advertising reporting unit taken in Q2 FY26 ($0.17/sh). No further impairment assumed - an explicit choice, not an absence of one.
B19: GAAP operating income (EBIT) | C19: =C10-C12-C14-C16-C17-C18 | D19: =D10-D12-D14-D16-D17-D18 | E19: =E10-E12-E14-E16-E17-E18 | F19: =F10-F12-F14-F16-F17-F18 | G19: =G10-G12-G14-G16-G17-G18 | H19: =H10-H12-H14-H16-H17-H18 | I19: =I10-I12-I14-I16-I17-I18 | K19: Ties to reported: FY24 $6,741mm, FY25 $8,706mm. FY26E lands ~$9.27bn vs the ~$9.24bn implied by the company's own GAAP EPS guidance and tax-rate/share-count assumptions.
B20: GAAP operating margin % | C20: =IFERROR(C19/C6,"n/a") | D20: =IFERROR(D19/D6,"n/a") | E20: =IFERROR(E19/E6,"n/a") | F20: =IFERROR(F19/F6,"n/a") | G20: =IFERROR(G19/G6,"n/a") | H20: =IFERROR(H19/H6,"n/a") | I20: =IFERROR(I19/I6,"n/a")
B22: Yield on cash & short-term investments (assumption) | E22: 0.036 | F22: 0.034 | G22: 0.033 | H22: 0.032 | I22: 0.032 | K22: Anchored to FY25 actual: $248mm of other income against ~$6.7bn average cash and investments = ~3.7%. Faded toward the forward short rate (FRED DGS3MO 3.84% on 27 Aug 2026). Runs off the PRIOR period's closing balances, which keeps the model acyclic.
B23: Blended interest rate on debt (assumption) | E23: 0.042 | F23: 0.042 | G23: 0.042 | H23: 0.042 | I23: 0.042 | K23: FY25 interest expense of $263mm against ~$5.2bn average debt implies ~5.0%; Q2 FY26 interest expense of $65mm against $6,645mm of debt annualises to ~3.9%. 4.2% is the midpoint.
B24: Interest & investment income | C24: 311 | D24: 248 | E24: =('Balance Sheet'!D6+'Balance Sheet'!D7)*E22 | F24: =('Balance Sheet'!E6+'Balance Sheet'!E7)*F22 | G24: =('Balance Sheet'!F6+'Balance Sheet'!F7)*G22 | H24: =('Balance Sheet'!G6+'Balance Sheet'!G7)*H22 | I24: =('Balance Sheet'!H6+'Balance Sheet'!H7)*I22 | K24: FY24/FY25 = reported 'other income (expense), net', which for Adobe is overwhelmingly interest on cash and investments. Forecast = prior-period closing (cash + STI) x the yield above.
B25: Interest expense | C25: -169 | D25: -263 | E25: =-'Balance Sheet'!D37*E23 | F25: =-'Balance Sheet'!E37*F23 | G25: =-'Balance Sheet'!F37*G23 | H25: =-'Balance Sheet'!G37*H23 | I25: =-'Balance Sheet'!H37*I23 | K25: FY24/FY25 derived from reported pre-tax income less operating income and the other non-operating components. Forecast = prior-period closing total debt x the blended rate above.
B26: Investment gains / (losses), net | C26: 48 | D26: 43 | E26: 0 | F26: 0 | G26: 0 | H26: 0 | I26: 0 | K26: Reported actuals. Held at ZERO in every forecast year on purpose: these are mark-to-market moves on a venture portfolio and extrapolating them would flatter forward earnings with something that is not operating performance.
B27: Pre-tax income | C27: =C19+C24+C25+C26 | D27: =D19+D24+D25+D26 | E27: =E19+E24+E25+E26 | F27: =F19+F24+F25+F26 | G27: =G19+G24+G25+G26 | H27: =H19+H24+H25+H26 | I27: =I19+I24+I25+I26 | K27: Ties to reported: FY24 $6,931mm, FY25 $8,734mm.
B28: Effective tax rate | C28: =1371/C27 | D28: =1604/D27 | E28: 0.225 | F28: 0.215 | G28: 0.21 | H28: 0.21 | I28: 0.21 | K28: FY24/FY25 = reported tax expense over reported pre-tax income (18.4% in FY25 - unusually low, helped by discrete items). Adobe guides ~22.5% GAAP for FY26; the forecast eases to 21% thereafter.
B29: Income tax expense | C29: =C27*C28 | D29: =D27*D28 | E29: =E27*E28 | F29: =F27*F28 | G29: =G27*G28 | H29: =H27*H28 | I29: =I27*I28
B30: GAAP net income | C30: =C27-C29 | D30: =D27-D29 | E30: =E27-E29 | F30: =F27-F29 | G30: =G27-G29 | H30: =H27-H29 | I30: =I27-I29 | K30: Ties to reported: FY24 $5,560mm, FY25 $7,130mm.
B32: Assumed annual share price appreciation (buyback execution) | E32: 0.08 | F32: 0.08 | G32: 0.08 | H32: 0.08 | I32: 0.08 | K32: Holding the buyback at TODAY'S price while modelled EPS compounds at ~17% is internally inconsistent: it retires shares at a price the model's own earnings growth says will not persist. 8% a year is a deliberate, editable middle course; set it to 0% to see the maximum-retirement case, which adds roughly 8% to FY2030E EPS.
B33: Assumed share price for buybacks & SBC issuance ($) | E33: =Cover_Price | F33: =E33*(1+F32) | G33: =F33*(1+G32) | H33: =G33*(1+H32) | I33: =H33*(1+I32) | K33: FY2026E executes at the 28 Aug 2026 close; later years compound at the rate above. Note this affects EPS only — it does NOT touch the DCF, because unlevered free cash flow is measured before financing.
B34: SBC-to-share-issuance factor (net of tax withholding) | E34: 0.55 | F34: 0.55 | G34: 0.55 | H34: 0.55 | I34: 0.55 | K34: Fraction of gross SBC dollars that actually becomes NEW shares after RSUs are net-settled for tax. 0.55 is a market-typical net-settlement retention; a 1.00 factor (maximum dilution) would cut FY30E EPS by roughly 2%.
B35: Shares outstanding, END of period (mm) | C35: 441 | D35: 413 | E35: =D35+('Cash Flow & Working Capital'!E20*E34)/E33+'Cash Flow & Working Capital'!E26/E33 | F35: =E35+('Cash Flow & Working Capital'!F20*F34)/F33+'Cash Flow & Working Capital'!F26/F33 | G35: =F35+('Cash Flow & Working Capital'!G20*G34)/G33+'Cash Flow & Working Capital'!G26/G33 | H35: =G35+('Cash Flow & Working Capital'!H20*H34)/H33+'Cash Flow & Working Capital'!H26/H33 | I35: =H35+('Cash Flow & Working Capital'!I20*I34)/I33+'Cash Flow & Working Capital'!I26/I33 | K35: FY24 (441mm at 29 Nov 2024) and FY25 (413mm at 28 Nov 2025) per the 10-Q/10-K cover and balance sheet share counts. Forecast = prior end + SBC-driven issuance - buyback retirement, both at TODAY'S share price. If the stock keeps rising, buybacks retire fewer shares than modelled.
B36: Diluted shares, weighted average (mm) | C36: 450 | D36: =AVERAGE(C35,D35) | E36: =AVERAGE(D35,E35) | F36: =AVERAGE(E35,F35) | G36: =AVERAGE(F35,G35) | H36: =AVERAGE(G35,H35) | I36: =AVERAGE(H35,I35) | K36: Modelled as the average of opening and closing share count. Validation: AVERAGE(441, 413) = 427.0mm, which is EXACTLY Adobe's reported FY2025 diluted weighted-average share count; and the FY26E output of ~400mm matches the ~399mm the company assumes in its own FY26 guidance.
B37: GAAP diluted EPS | C37: =IFERROR(C30/C36,"n/a") | D37: =IFERROR(D30/D36,"n/a") | E37: =IFERROR(E30/E36,"n/a") | F37: =IFERROR(F30/F36,"n/a") | G37: =IFERROR(G30/G36,"n/a") | H37: =IFERROR(H30/H36,"n/a") | I37: =IFERROR(I30/I36,"n/a") | K37: Ties to reported: FY24 $12.36, FY25 $16.70. FY26E lands inside the company's $17.90-18.00 guide.
B38: Non-GAAP tax rate (assumption) | E38: 0.18 | F38: 0.18 | G38: 0.18 | H38: 0.18 | I38: 0.18 | K38: Company guidance assumes ~18.0% for FY26.
B39: MEMO: non-GAAP diluted EPS (model approximation) | E39: =IFERROR(((E19+'Cash Flow & Working Capital'!E20+E17+E18+E24+E25)*(1-E38))/E36,"n/a") | F39: =IFERROR(((F19+'Cash Flow & Working Capital'!F20+F17+F18+F24+F25)*(1-F38))/F36,"n/a") | G39: =IFERROR(((G19+'Cash Flow & Working Capital'!G20+G17+G18+G24+G25)*(1-G38))/G36,"n/a") | H39: =IFERROR(((H19+'Cash Flow & Working Capital'!H20+H17+H18+H24+H25)*(1-H38))/H36,"n/a") | I39: =IFERROR(((I19+'Cash Flow & Working Capital'!I20+I17+I18+I24+I25)*(1-I38))/I36,"n/a") | K39: Adds back SBC, intangible amortisation and the goodwill impairment, taxed at the non-GAAP rate. This lands ~2% BELOW the company's own $24.35-24.45 FY26 non-GAAP guide because Adobe adds back 'stock-based AND DEFERRED compensation', which runs ~4% above the SBC cash-flow line. Treat this row as a reconciliation aid, not as the company's measure.

Sheet Balance Sheet
A2: BALANCE SHEET — $mm
B3: FY2025A (28 Nov 2025) is the historical anchor and is FULLY ITEMISED from the reported balance sheet — every line below is a real reported caption, so this model needs NO reconciling plug and total assets tie to the reported $29,496mm exactly. FY2024A is not built out as a full balance sheet; the projection only needs one clean starting point to roll forward from.
C5: FY2024A | D5: FY2025A | E5: FY2026E | F5: FY2027E | G5: FY2028E | H5: FY2029E | I5: FY2030E
B6: Cash & cash equivalents | D6: 5431 | E6: =D6+'Cash Flow & Working Capital'!E32 | F6: =E6+'Cash Flow & Working Capital'!F32 | G6: =F6+'Cash Flow & Working Capital'!G32 | H6: =G6+'Cash Flow & Working Capital'!H32 | I6: =H6+'Cash Flow & Working Capital'!I32 | K6: Plug — computed on the Cash Flow tab and linked here.
B7: Short-term investments | D7: 1164 | E7: 1164 | F7: 1164 | G7: 1164 | H7: 1164 | I7: 1164 | K7: Held flat — Adobe manages this as an excess-cash sleeve, not a growing portfolio.
B8: Trade receivables, net | D8: 2344 | E8: =('Cash Flow & Working Capital'!E5/365)*'Income Statement'!E6 | F8: =('Cash Flow & Working Capital'!F5/365)*'Income Statement'!F6 | G8: =('Cash Flow & Working Capital'!G5/365)*'Income Statement'!G6 | H8: =('Cash Flow & Working Capital'!H5/365)*'Income Statement'!H6 | I8: =('Cash Flow & Working Capital'!I5/365)*'Income Statement'!I6 | K8: Projected via DSO on the Cash Flow tab.
B9: Prepaid expenses & other current assets | D9: 1224 | E9: ='Income Statement'!E6*'Cash Flow & Working Capital'!E6 | F9: ='Income Statement'!F6*'Cash Flow & Working Capital'!F6 | G9: ='Income Statement'!G6*'Cash Flow & Working Capital'!G6 | H9: ='Income Statement'!H6*'Cash Flow & Working Capital'!H6 | I9: ='Income Statement'!I6*'Cash Flow & Working Capital'!I6 | K9: Projected as % of revenue.
B10: Total current assets | D10: =D6+D7+D8+D9 | E10: =E6+E7+E8+E9 | F10: =F6+F7+F8+F9 | G10: =G6+G7+G8+G9 | H10: =H6+H7+H8+H9 | I10: =I6+I7+I8+I9
B11: Property & equipment, net | D11: 1873 | E11: =D11+'Cash Flow & Working Capital'!E12-'Cash Flow & Working Capital'!E13 | F11: =E11+'Cash Flow & Working Capital'!F12-'Cash Flow & Working Capital'!F13 | G11: =F11+'Cash Flow & Working Capital'!G12-'Cash Flow & Working Capital'!G13 | H11: =G11+'Cash Flow & Working Capital'!H12-'Cash Flow & Working Capital'!H13 | I11: =H11+'Cash Flow & Working Capital'!I12-'Cash Flow & Working Capital'!I13 | K11: Rolls forward: prior + capex - depreciation.
B12: Operating lease right-of-use assets | D12: 312 | E12: 312 | F12: 312 | G12: 312 | H12: 312 | I12: 312 | K12: Held flat.
B13: Goodwill | D13: 12857 | E13: =D13+'Cash Flow & Working Capital'!E28-'Income Statement'!E18 | F13: =E13+'Cash Flow & Working Capital'!F28-'Income Statement'!F18 | G13: =F13+'Cash Flow & Working Capital'!G28-'Income Statement'!G18 | H13: =G13+'Cash Flow & Working Capital'!H28-'Income Statement'!H18 | I13: =H13+'Cash Flow & Working Capital'!I28-'Income Statement'!I18 | K13: Rolls forward: prior + goodwill from acquisitions - impairment. FY26E lands at $14,041mm, the reported Q2 FY26 balance.
B14: Other intangibles, net | D14: 495 | E14: =D14+'Cash Flow & Working Capital'!E29-'Income Statement'!E17 | F14: =E14+'Cash Flow & Working Capital'!F29-'Income Statement'!F17 | G14: =F14+'Cash Flow & Working Capital'!G29-'Income Statement'!G17 | H14: =G14+'Cash Flow & Working Capital'!H29-'Income Statement'!H17 | I14: =H14+'Cash Flow & Working Capital'!I29-'Income Statement'!I17 | K14: Rolls forward: prior + intangibles from acquisitions - amortisation (Income Statement).
B15: Deferred income taxes | D15: 2186 | E15: 2186 | F15: 2186 | G15: 2186 | H15: 2186 | I15: 2186 | K15: Held flat — genuinely unpredictable, and holding it flat needs no offsetting cash-flow line.
B16: Other assets | D16: 1610 | E16: 1610 | F16: 1610 | G16: 1610 | H16: 1610 | I16: 1610 | K16: Held flat.
B17: Total assets | D17: =D10+D11+D12+D13+D14+D15+D16 | E17: =E10+E11+E12+E13+E14+E15+E16 | F17: =F10+F11+F12+F13+F14+F15+F16 | G17: =G10+G11+G12+G13+G14+G15+G16 | H17: =H10+H11+H12+H13+H14+H15+H16 | I17: =I10+I11+I12+I13+I14+I15+I16 | K17: FY2025A ties to the reported $29,496mm.
B19: Trade payables | D19: 417 | E19: ='Income Statement'!E6*'Cash Flow & Working Capital'!E7 | F19: ='Income Statement'!F6*'Cash Flow & Working Capital'!F7 | G19: ='Income Statement'!G6*'Cash Flow & Working Capital'!G7 | H19: ='Income Statement'!H6*'Cash Flow & Working Capital'!H7 | I19: ='Income Statement'!I6*'Cash Flow & Working Capital'!I7 | K19: Projected as % of revenue.
B20: Accrued expenses & other current liabilities | D20: 2648 | E20: ='Income Statement'!E6*'Cash Flow & Working Capital'!E8 | F20: ='Income Statement'!F6*'Cash Flow & Working Capital'!F8 | G20: ='Income Statement'!G6*'Cash Flow & Working Capital'!G8 | H20: ='Income Statement'!H6*'Cash Flow & Working Capital'!H8 | I20: ='Income Statement'!I6*'Cash Flow & Working Capital'!I8 | K20: Projected as % of revenue.
B21: Debt, current | D21: 0 | E21: 1843 | F21: 0 | G21: 0 | H21: 0 | I21: 0 | K21: FY26E = the $1,843mm current portion reported at 29 May 2026, repaid in FY27E. Any change here flows to the financing line on the Cash Flow tab automatically.
B22: Deferred revenue, current | D22: 6905 | E22: ='Income Statement'!E6*'Cash Flow & Working Capital'!E9 | F22: ='Income Statement'!F6*'Cash Flow & Working Capital'!F9 | G22: ='Income Statement'!G6*'Cash Flow & Working Capital'!G9 | H22: ='Income Statement'!H6*'Cash Flow & Working Capital'!H9 | I22: ='Income Statement'!I6*'Cash Flow & Working Capital'!I9 | K22: Projected as % of revenue — the largest single working-capital source of cash in the model.
B23: Income taxes payable, current | D23: 153 | E23: 153 | F23: 153 | G23: 153 | H23: 153 | I23: 153 | K23: Held flat.
B24: Operating lease liabilities, current | D24: 77 | E24: 77 | F24: 77 | G24: 77 | H24: 77 | I24: 77 | K24: Held flat.
B25: Total current liabilities | D25: =D19+D20+D21+D22+D23+D24 | E25: =E19+E20+E21+E22+E23+E24 | F25: =F19+F20+F21+F22+F23+F24 | G25: =G19+G20+G21+G22+G23+G24 | H25: =H19+H20+H21+H22+H23+H24 | I25: =I19+I20+I21+I22+I23+I24
B26: Debt, long-term | D26: 6210 | E26: 4802 | F26: 4802 | G26: 4802 | H26: 4802 | I26: 4802 | K26: FY25 $6,210mm reported. FY26E-onward $4,802mm is the long-term portion reported at 29 May 2026 after Adobe reclassified $1,843mm to current and drew $493mm to help fund Semrush.
B27: Deferred revenue, long-term | D27: 125 | E27: ='Income Statement'!E6*'Cash Flow & Working Capital'!E10 | F27: ='Income Statement'!F6*'Cash Flow & Working Capital'!F10 | G27: ='Income Statement'!G6*'Cash Flow & Working Capital'!G10 | H27: ='Income Statement'!H6*'Cash Flow & Working Capital'!H10 | I27: ='Income Statement'!I6*'Cash Flow & Working Capital'!I10 | K27: Projected as % of revenue.
B28: Income taxes payable, long-term | D28: 469 | E28: 469 | F28: 469 | G28: 469 | H28: 469 | I28: 469 | K28: Held flat.
B29: Operating lease liabilities, long-term | D29: 361 | E29: 361 | F29: 361 | G29: 361 | H29: 361 | I29: 361 | K29: Held flat.
B30: Other long-term liabilities | D30: 508 | E30: =D30+'Cash Flow & Working Capital'!E30 | F30: =E30+'Cash Flow & Working Capital'!F30 | G30: =F30+'Cash Flow & Working Capital'!G30 | H30: =G30+'Cash Flow & Working Capital'!H30 | I30: =H30+'Cash Flow & Working Capital'!I30 | K30: Rolls forward with net liabilities assumed on acquisitions (Cash Flow tab), otherwise flat.
B31: Total liabilities | D31: =D25+D26+D27+D28+D29+D30 | E31: =E25+E26+E27+E28+E29+E30 | F31: =F25+F26+F27+F28+F29+F30 | G31: =G25+G26+G27+G28+G29+G30 | H31: =H25+H26+H27+H28+H29+H30 | I31: =I25+I26+I27+I28+I29+I30 | K31: FY2025A ties to the reported $17,873mm.
B32: Stockholders' equity, beginning of period | E32: =D33 | F32: =E33 | G32: =F33 | H32: =G33 | I32: =H33
B33: Stockholders' equity, end of period | D33: 11623 | E33: =E32+'Income Statement'!E30+'Cash Flow & Working Capital'!E20+'Cash Flow & Working Capital'!E26 | F33: =F32+'Income Statement'!F30+'Cash Flow & Working Capital'!F20+'Cash Flow & Working Capital'!F26 | G33: =G32+'Income Statement'!G30+'Cash Flow & Working Capital'!G20+'Cash Flow & Working Capital'!G26 | H33: =H32+'Income Statement'!H30+'Cash Flow & Working Capital'!H20+'Cash Flow & Working Capital'!H26 | I33: =I32+'Income Statement'!I30+'Cash Flow & Working Capital'!I20+'Cash Flow & Working Capital'!I26 | K33: FY2025A ties to the reported $11,623mm. Forecast = opening equity + net income + SBC - buybacks. The SBC add-back on the EQUITY side (not just in cash) is what keeps the balance sheet tying: SBC credits additional paid-in capital in real accounting.
B34: Total liabilities & equity | D34: =D31+D33 | E34: =E31+E33 | F34: =F31+F33 | G34: =G31+G33 | H34: =H31+H33 | I34: =I31+I33
B35: Balance check (assets less liabilities & equity) | D35: =D17-D34 | E35: =E17-E34 | F35: =F17-F34 | G35: =G17-G34 | H35: =H17-H34 | I35: =I17-I34 | K35: Must read exactly 0 in every populated column.
B37: MEMO: total debt (current + long-term) | D37: =D21+D26 | E37: =E21+E26 | F37: =F21+F26 | G37: =G21+G26 | H37: =H21+H26 | I37: =I21+I26
B38: MEMO: net cash / (net debt) | D38: =D6+D7-D37 | E38: =E6+E7-E37 | F38: =F6+F7-F37 | G38: =G6+G7-G37 | H38: =H6+H7-H37 | I38: =I6+I7-I37 | K38: Adobe moved from ~$0.4bn net cash at FY25 to ~$1.0bn NET DEBT after paying $1.87bn cash for Semrush.

Sheet Cash Flow & Working Capital
A2: WORKING CAPITAL, CAPEX & DEPRECIATION SCHEDULES
C4: FY2024A | D4: FY2025A | E4: FY2026E | F4: FY2027E | G4: FY2028E | H4: FY2029E | I4: FY2030E
B5: Days sales outstanding (AR / revenue x 365) | D5: =2344/'Income Statement'!D6*365 | E5: 35.5 | F5: 35 | G5: 35 | H5: 35 | I5: 35 | K5: FY25 actual 36.0 days. Adobe collects fast because most of the base is card-billed subscriptions.
B6: Prepaid & other current assets, % of revenue | D6: =1224/'Income Statement'!D6 | E6: 0.052 | F6: 0.052 | G6: 0.052 | H6: 0.052 | I6: 0.052
B7: Trade payables, % of revenue | D7: =417/'Income Statement'!D6 | E7: 0.018 | F7: 0.018 | G7: 0.018 | H7: 0.018 | I7: 0.018
B8: Accrued expenses, % of revenue | D8: =2648/'Income Statement'!D6 | E8: 0.111 | F8: 0.111 | G8: 0.111 | H8: 0.111 | I8: 0.111
B9: Deferred revenue (current), % of revenue | D9: =6905/'Income Statement'!D6 | E9: 0.29 | F9: 0.287 | G9: 0.284 | H9: 0.282 | I9: 0.28 | K9: FY25 actual 29.05%. The gentle fade is a real thesis: generative-credit and consumption pricing is recognised on USE rather than billed a year in advance, so a mix shift toward AI monetisation structurally shrinks deferred revenue as a share of sales — and with it a cash-flow tailwind Adobe has enjoyed for a decade.
B10: Deferred revenue (long-term), % of revenue | D10: =125/'Income Statement'!D6 | E10: 0.005 | F10: 0.005 | G10: 0.005 | H10: 0.005 | I10: 0.005
B11: Capex % of revenue | D11: =179/'Income Statement'!D6 | E11: 0.008 | F11: 0.008 | G11: 0.008 | H11: 0.008 | I11: 0.008 | K11: FY25 actual 0.75%. Adobe is strikingly asset-light: it rents AI compute rather than building it, so inference cost lands in COGS (gross margin) instead of capex. A decision to bring model training in-house would break this assumption — watch for it.
B12: Capital expenditures | D12: ='Income Statement'!D6*D11 | E12: ='Income Statement'!E6*E11 | F12: ='Income Statement'!F6*F11 | G12: ='Income Statement'!G6*G11 | H12: ='Income Statement'!H6*H11 | I12: ='Income Statement'!I6*I11
B13: Depreciation (excl. intangible amortisation) | D13: 508 | E13: 480 | F13: 430 | G13: 380 | H13: 340 | I13: 310 | K13: FY25: reported total D&A of $818mm less $310mm of intangible amortisation. Adobe has been shrinking its PP&E base — depreciation runs at roughly 3x capex as it sheds real estate — so the forecast fades depreciation toward the capex run-rate. Extrapolating $520mm/yr against $200mm of capex drives net PP&E to zero by FY2030, which is not a forecast but an arithmetic accident.
B14: Total D&A (depreciation + intangible amortisation) | D14: =D13+'Income Statement'!D17 | E14: =E13+'Income Statement'!E17 | F14: =F13+'Income Statement'!F17 | G14: =G13+'Income Statement'!G17 | H14: =H13+'Income Statement'!H17 | I14: =I13+'Income Statement'!I17
A16: CASH FLOW STATEMENT — links the Income Statement to the Balance Sheet
C17: FY2024A | D17: FY2025A | E17: FY2026E | F17: FY2027E | G17: FY2028E | H17: FY2029E | I17: FY2030E
B18: Net income | D18: ='Income Statement'!D30 | E18: ='Income Statement'!E30 | F18: ='Income Statement'!F30 | G18: ='Income Statement'!G30 | H18: ='Income Statement'!H30 | I18: ='Income Statement'!I30
B19: + Depreciation & amortisation | D19: =D14 | E19: =E14 | F19: =F14 | G19: =G14 | H19: =H14 | I19: =I14
B20: + Stock-based compensation | D20: 1942 | E20: 2120 | F20: 2270 | G20: 2400 | H20: 2520 | I20: 2630 | K20: FY25 actual $1,942mm (8.2% of revenue). H1 FY26 was already $1,043mm. Forecast grows with headcount and revenue but as a slowly declining share of sales.
B21: + Goodwill impairment (non-cash) | D21: ='Income Statement'!D18 | E21: ='Income Statement'!E18 | F21: ='Income Statement'!F18 | G21: ='Income Statement'!G18 | H21: ='Income Statement'!H18 | I21: ='Income Statement'!I18 | K21: FY24's $1,000mm Figma termination fee was a CASH cost, so this add-back is only correct from FY25 onward — FY2024 is not built out as a cash-flow year and the column is deliberately blank.
B22: +/- Change in net working capital | D22: 141 | E22: =-(('Balance Sheet'!E8-'Balance Sheet'!D8)+('Balance Sheet'!E9-'Balance Sheet'!D9)-('Balance Sheet'!E19-'Balance Sheet'!D19)-('Balance Sheet'!E20-'Balance Sheet'!D20)-('Balance Sheet'!E22-'Balance Sheet'!D22)-('Balance Sheet'!E27-'Balance Sheet'!D27)) | F22: =-(('Balance Sheet'!F8-'Balance Sheet'!E8)+('Balance Sheet'!F9-'Balance Sheet'!E9)-('Balance Sheet'!F19-'Balance Sheet'!E19)-('Balance Sheet'!F20-'Balance Sheet'!E20)-('Balance Sheet'!F22-'Balance Sheet'!E22)-('Balance Sheet'!F27-'Balance Sheet'!E27)) | G22: =-(('Balance Sheet'!G8-'Balance Sheet'!F8)+('Balance Sheet'!G9-'Balance Sheet'!F9)-('Balance Sheet'!G19-'Balance Sheet'!F19)-('Balance Sheet'!G20-'Balance Sheet'!F20)-('Balance Sheet'!G22-'Balance Sheet'!F22)-('Balance Sheet'!G27-'Balance Sheet'!F27)) | H22: =-(('Balance Sheet'!H8-'Balance Sheet'!G8)+('Balance Sheet'!H9-'Balance Sheet'!G9)-('Balance Sheet'!H19-'Balance Sheet'!G19)-('Balance Sheet'!H20-'Balance Sheet'!G20)-('Balance Sheet'!H22-'Balance Sheet'!G22)-('Balance Sheet'!H27-'Balance Sheet'!G27)) | I22: =-(('Balance Sheet'!I8-'Balance Sheet'!H8)+('Balance Sheet'!I9-'Balance Sheet'!H9)-('Balance Sheet'!I19-'Balance Sheet'!H19)-('Balance Sheet'!I20-'Balance Sheet'!H20)-('Balance Sheet'!I22-'Balance Sheet'!H22)-('Balance Sheet'!I27-'Balance Sheet'!H27)) | K22: FY2025A is an ANCHOR column, not a full reconciliation: $141mm is the residual that makes modelled CFO tie to the reported $10,031mm, and it bundles the real working-capital swing with other non-cash items (deferred taxes, FX) this model does not itemise. Net change in cash and net debt issuance are left BLANK for FY2025A because the FY2024 balance sheet is not built out. FY2026E onward is fully formula-driven.
B23: Cash from operations | D23: =D18+D19+D20+D21+D22 | E23: =E18+E19+E20+E21+E22 | F23: =F18+F19+F20+F21+F22 | G23: =G18+G19+G20+G21+G22 | H23: =H18+H19+H20+H21+H22 | I23: =I18+I19+I20+I21+I22 | K23: FY2025A output should land near the reported $10,031mm.
B24: - Capital expenditures | D24: =-D12 | E24: =-E12 | F24: =-F12 | G24: =-G12 | H24: =-H12 | I24: =-I12
B25: Free cash flow (levered, after SBC add-back) | D25: =D23+D24 | E25: =E23+E24 | F25: =F23+F24 | G25: =G23+G24 | H25: =H23+H24 | I25: =I23+I24 | K25: NOT the same as unlevered FCF on the DCF tab, and the gap is intentional: this line adds SBC back as non-cash and is stated after interest and tax as paid. The DCF starts from EBIT and does NOT add SBC back, because SBC is a real cost of compensating employees and adding it back while also diluting the share count would count the same benefit twice.
B26: - Share repurchases | D26: -11281 | E26: -9000 | F26: -10500 | G26: -11500 | H26: -12500 | I26: -13500 | K26: FY25 actual $11,281mm (30.8mm shares) — more than 100% of that year's free cash flow. H1 FY26 was $4,589mm, annualising near $9bn. The forecast ramps with free cash flow because that is what Adobe actually does; holding it flat at $8bn piles up an implausible ~$25bn of idle cash by FY2030. $27bn remained under authorisation at Q2 FY26 (including $25bn authorised in April 2026), so the FY28E-FY30E pace ASSUMES further authorisations. Adobe has reauthorised repeatedly, but that is an assumption, not a commitment.
B27: - Acquisitions, net of cash acquired | D27: -17 | E27: -1560 | F27: 0 | G27: 0 | H27: 0 | I27: 0 | K27: FY26E = the $1,560mm net cash outflow for Semrush reported in Q2 FY26 (headline price $1.87bn, $12.00/share). No further M&A assumed.
B28: of which: goodwill recognised | D28: 0 | E28: 1254 | F28: 0 | G28: 0 | H28: 0 | I28: 0
B29: of which: intangibles recognised | D29: 0 | E29: 517 | F29: 0 | G29: 0 | H29: 0 | I29: 0
B30: of which: net liabilities assumed (balancing) | D30: =D28+D29+D27 | E30: =E28+E29+E27 | F30: =F28+F29+F27 | G30: =G28+G29+G27 | H30: =H28+H29+H27 | I30: =I28+I29+I27 | K30: Formula, not an input: goodwill + intangibles less cash paid. Keeps the acquisition self-balancing if you change the purchase-price allocation above.
B31: +/- Net debt issuance / (repayment) | E31: ='Balance Sheet'!E37-'Balance Sheet'!D37 | F31: ='Balance Sheet'!F37-'Balance Sheet'!E37 | G31: ='Balance Sheet'!G37-'Balance Sheet'!F37 | H31: ='Balance Sheet'!H37-'Balance Sheet'!G37 | I31: ='Balance Sheet'!I37-'Balance Sheet'!H37 | K31: Formula: period-over-period change in total debt on the Balance Sheet, so the FY27E repayment of the $1,843mm current portion appears as a financing outflow instead of silently breaking the balance sheet.
B32: Net change in cash | E32: =E25+E26+E27+E31 | F32: =F25+F26+F27+F31 | G32: =G25+G26+G27+G31 | H32: =H25+H26+H27+H31 | I32: =I25+I26+I27+I31 | K32: Left blank for FY2025A: without a FY2024 balance sheet there is no debt-issuance or investment-transfer figure to reconcile against, and a partial number would read like a complete one.

Sheet DCF & WACC
A2: WACC BUILD
B3: Risk-free rate (10-yr US Treasury) | D3: 0.0467 | I3: FRED series DGS10, observation 27 Aug 2026 (4.67%).
B4: Equity risk premium | D4: 0.045 | I4: MODEL ASSUMPTION. 4.5% is a conventional forward-looking US ERP. This figure was NOT independently verified against Damodaran's current published update in building this model — treat it as the single least-sourced input on this tab and check it before relying on the WACC.
B5: Beta (5-year) | D5: 1.4 | I5: stockanalysis.com, 28 Aug 2026. Beta methodologies differ materially between providers; a 1.20 beta would cut WACC by ~0.85pt and lift the DCF value roughly 15%.
B6: Cost of equity (CAPM = Rf + Beta x ERP) | D6: =D3+D5*D4
B8: Pre-tax cost of debt | D8: 0.042 | I8: Blended rate on Adobe's actual debt stack — consistent with the assumption on the Income Statement tab and derived from reported interest expense over average debt.
B9: Marginal tax rate (for the debt tax shield) | D9: 0.21 | I9: US federal statutory rate.
B10: After-tax cost of debt | D10: =D8*(1-D9)
B12: Market value of equity ($mm) | D12: =Cover_MktCap
B13: Market value of debt ($mm) | D13: =Cover_Debt
B14: Weight of equity | D14: =D12/(D12+D13)
B15: Weight of debt | D15: =D13/(D12+D13)
B16: WACC | D16: =D14*D6+D15*D10
B17: Adobe carries $6.6bn of debt against a ~$116bn market cap, so debt is ~5% of capital and the tax shield barely moves the number: WACC here is effectively the cost of equity, and the output is therefore almost entirely a function of the beta and ERP assumptions above.
A19: UNLEVERED FREE CASH FLOW (FY2026E-FY2030E)
C20: FY2026E | D20: FY2027E | E20: FY2028E | F20: FY2029E | G20: FY2030E
B21: EBIT | C21: ='Income Statement'!E19 | D21: ='Income Statement'!F19 | E21: ='Income Statement'!G19 | F21: ='Income Statement'!H19 | G21: ='Income Statement'!I19
B22: NOPAT (EBIT x (1 - effective tax rate)) | C22: =C21*(1-'Income Statement'!E28) | D22: =D21*(1-'Income Statement'!F28) | E22: =E21*(1-'Income Statement'!G28) | F22: =F21*(1-'Income Statement'!H28) | G22: =G21*(1-'Income Statement'!I28)
B23: + D&A | C23: ='Cash Flow & Working Capital'!E14 | D23: ='Cash Flow & Working Capital'!F14 | E23: ='Cash Flow & Working Capital'!G14 | F23: ='Cash Flow & Working Capital'!H14 | G23: ='Cash Flow & Working Capital'!I14
B24: - Capex | C24: =-'Cash Flow & Working Capital'!E12 | D24: =-'Cash Flow & Working Capital'!F12 | E24: =-'Cash Flow & Working Capital'!G12 | F24: =-'Cash Flow & Working Capital'!H12 | G24: =-'Cash Flow & Working Capital'!I12
B25: +/- Change in net working capital | C25: ='Cash Flow & Working Capital'!E22 | D25: ='Cash Flow & Working Capital'!F22 | E25: ='Cash Flow & Working Capital'!G22 | F25: ='Cash Flow & Working Capital'!H22 | G25: ='Cash Flow & Working Capital'!I22 | I25: Positive for Adobe: deferred revenue grows faster than receivables, so working capital is a SOURCE of cash. This is a real and underappreciated part of the FCF story — and it fades in the model as consumption pricing dilutes deferred revenue.
B26: Unlevered free cash flow | C26: =C22+C23+C24+C25 | D26: =D22+D23+D24+D25 | E26: =E22+E23+E24+E25 | F26: =F22+F23+F24+F25 | G26: =G22+G23+G24+G25
B27: Discount period (years, mid-year convention) | C27: 0.5 | D27: 1.5 | E27: 2.5 | F27: 3.5 | G27: 4.5 | I27: Mid-year convention. Note this is CONSERVATIVE for FY2026E, which is already three-quarters elapsed as of the 29 Aug 2026 model date — a strict as-of-today discounting would use ~0.1 years and produce a slightly higher value.
B28: Discount factor | C28: =1/(1+D16)^C27 | D28: =1/(1+D16)^D27 | E28: =1/(1+D16)^E27 | F28: =1/(1+D16)^F27 | G28: =1/(1+D16)^G27
B29: PV of unlevered FCF | C29: =C26*C28 | D29: =D26*D28 | E29: =E26*E28 | F29: =F26*F28 | G29: =G26*G28
A31: TERMINAL VALUE, ENTERPRISE VALUE & IMPLIED PRICE
B32: Terminal growth rate | D32: 0.03 | I32: Roughly long-run nominal GDP. Compare against the REVERSE-DCF block below, which backs out what today's share price is actually implying.
B33: Terminal-year unlevered FCF (FY2030E x (1+g)) | D33: =G26*(1+D32)
B34: Terminal value (Gordon growth) | D34: =IF(D32>=D16,"n/m",D33/(D16-D32))
B35: PV of terminal value | D35: =IFERROR(D34*G28,"n/m")
B36: Sum of PV of explicit-period FCF | D36: =SUM(C29:G29)
B37: Enterprise value ($mm) | D37: =D36+D35
B38: Terminal value as % of enterprise value | D38: =IFERROR(D35/D37,"n/m") | I38: Read this. Above ~85% the DCF is an exit-multiple opinion wearing a DCF's clothing.
B39: DCF-implied terminal EV/EBITDA multiple | D39: =IFERROR(D34/(G21+G23),"n/m") | I39: Terminal value divided by FY2030E EBITDA. The Scenarios tab CALIBRATES its Base-case exit multiple to this number rather than picking one independently — otherwise the two valuation methods diverge for no reason other than an unexamined assumption.
B40: Plus: net cash / (net debt) ($mm) | D40: =Cover_Cash-Cover_Debt
B41: Implied equity value ($mm) | D41: =D37+D40
B42: Shares outstanding (mm) | D42: =Cover_Shares
B43: Implied share price (DCF) | D43: =IFERROR(D41/D42,"n/m")
B44: Upside / (downside) vs. current price | D44: =IFERROR(D43/Cover_Price-1,"n/m")
A46: REVERSE DCF — WHAT IS THE CURRENT PRICE ACTUALLY ASSUMING?
...

Sheet Scenarios
A2: BEAR / BASE / BULL — DRIVEN BY THE ARR TRAJECTORY
B3: Each scenario is anchored on FY2026E, which is effectively locked by company guidance and three quarters of actuals, and then differs only in the four-year FY2026E-FY2030E path. All three divide by TODAY'S share count: a buyback does not create value in a DCF, it redistributes it, and dividing a Bull enterprise value by a smaller Bull share count would double-count the same cash flow.
C5: Bear | D5: Base | E5: Bull
B6: Scenario in one line | C6: Freemium fails to convert; AI substitution bites | D6: Freemium defers ARR, does not destroy it | E6: Freemium builds a second engine; AI is accretive
B7: FY2026E-FY2030E revenue CAGR (4 years) | C7: 0.035 | D7: =('Income Statement'!I6/'Income Statement'!E6)^(1/4)-1 | E7: 0.105 | G7: Base is a LIVE formula off the 3-statement model, so it cannot drift from it. Bear 3.5% assumes the H2 FY26 ARR air-pocket is structural and seat counts decline as AI substitutes for junior creative labour. Bull 11.5% assumes freemium conversion plus AI-first ARR compounding past $5bn by FY2030 — moderated from a first pass, because stacking four simultaneously optimistic assumptions is how a bull case stops being informative.
B8: FY2026E revenue ($mm) — same in all scenarios | C8: ='Income Statement'!E6 | D8: ='Income Statement'!E6 | E8: ='Income Statement'!E6
B9: FY2030E revenue ($mm) | C9: =C8*(1+C7)^4 | D9: =D8*(1+D7)^4 | E9: =E8*(1+E7)^4
B10: FY2030E GAAP operating margin | C10: 0.29 | D10: ='Income Statement'!I20 | E10: 0.395 | G10: Base is a LIVE link to the 3-statement model's FY2030E margin. Bear assumes generative-AI inference cost plus a permanently elevated customer-acquisition spend; Bull assumes the freemium funnel becomes organic and inference cost per generation keeps falling.
B11: FY2030E EBIT ($mm) | C11: =C9*C10 | D11: =D9*D10 | E11: =E9*E10
B12: FY2030E D&A ($mm) | C12: ='Cash Flow & Working Capital'!I14 | D12: ='Cash Flow & Working Capital'!I14 | E12: ='Cash Flow & Working Capital'!I14
B13: FY2030E EBITDA ($mm) | C13: =C11+C12 | D13: =D11+D12 | E13: =E11+E12
B14: Tax rate | C14: 0.21 | D14: 0.21 | E14: 0.21
B15: Capex % of revenue | C15: 0.012 | D15: 0.008 | E15: 0.008 | G15: Bear assumes Adobe is forced to bring more AI compute in-house to defend gross margin.
B16: Working-capital benefit, % of FY30 revenue growth | C16: 0.15 | D16: 0.28 | E16: 0.32 | G16: Deferred revenue growth net of receivables. Lower in Bear as consumption pricing displaces annual billings.
B17: FY2030E incremental revenue ($mm) | C17: =C9-C9/(1+C7) | D17: =D9-D9/(1+D7) | E17: =E9-E9/(1+E7)
B18: FY2030E unlevered free cash flow ($mm) | C18: =C11*(1-C14)+C12-C9*C15+C17*C16 | D18: =D11*(1-D14)+D12-D9*D15+D17*D16 | E18: =E11*(1-E14)+E12-E9*E15+E17*E16
B19: FY2026E unlevered free cash flow ($mm) — same in all scenarios | C19: ='DCF & WACC'!C26 | D19: ='DCF & WACC'!C26 | E19: ='DCF & WACC'!C26
B20: WACC | C20: 0.115 | D20: ='DCF & WACC'!D16 | E20: 0.102 | G20: Base is the CAPM build on the DCF tab. Bear widens it (higher beta in a disrupted franchise), Bull narrows it (a proven second growth engine de-risks the equity).
B21: Terminal growth rate | C21: 0.005 | D21: 0.03 | E21: 0.0325
B22: Exit EV/EBITDA multiple (FY2030E) | C22: 8 | D22: ='DCF & WACC'!D39 | E22: 13.5 | G22: The BASE exit multiple is CALIBRATED to the DCF-implied terminal multiple on the DCF tab, so the two methods below cannot diverge merely because someone picked a round number. Bear and Bull are given a real spread around that anchor on genuinely different quality assumptions.
A24: METHOD 1 — DISCOUNTED CASH FLOW
B25: PV of FY2026E-FY2030E unlevered FCF ($mm) | C25: =(C19*(C18/C19)^(0/4))/(1+C20)^0.5+(C19*(C18/C19)^(1/4))/(1+C20)^1.5+(C19*(C18/C19)^(2/4))/(1+C20)^2.5+(C19*(C18/C19)^(3/4))/(1+C20)^3.5+(C19*(C18/C19)^(4/4))/(1+C20)^4.5 | D25: =(D19*(D18/D19)^(0/4))/(1+D20)^0.5+(D19*(D18/D19)^(1/4))/(1+D20)^1.5+(D19*(D18/D19)^(2/4))/(1+D20)^2.5+(D19*(D18/D19)^(3/4))/(1+D20)^3.5+(D19*(D18/D19)^(4/4))/(1+D20)^4.5 | E25: =(E19*(E18/E19)^(0/4))/(1+E20)^0.5+(E19*(E18/E19)^(1/4))/(1+E20)^1.5+(E19*(E18/E19)^(2/4))/(1+E20)^2.5+(E19*(E18/E19)^(3/4))/(1+E20)^3.5+(E19*(E18/E19)^(4/4))/(1+E20)^4.5 | G25: The cash-flow path between the guided FY2026E figure and each scenario's FY2030E figure is interpolated geometrically, then discounted year by year on the same mid-year convention as the DCF tab.
B26: Terminal value ($mm) | C26: =IF(C21>=C20,"n/m",C18*(1+C21)/(C20-C21)) | D26: =IF(D21>=D20,"n/m",D18*(1+D21)/(D20-D21)) | E26: =IF(E21>=E20,"n/m",E18*(1+E21)/(E20-E21))
B27: PV of terminal value ($mm) | C27: =IFERROR(C26/(1+C20)^4.5,"n/m") | D27: =IFERROR(D26/(1+D20)^4.5,"n/m") | E27: =IFERROR(E26/(1+E20)^4.5,"n/m")
B28: Enterprise value ($mm) | C28: =IFERROR(C25+C27,"n/m") | D28: =IFERROR(D25+D27,"n/m") | E28: =IFERROR(E25+E27,"n/m")
B29: Implied share price — DCF | C29: =IFERROR((C28+Cover_Cash-Cover_Debt)/Cover_Shares,"n/m") | D29: =IFERROR((D28+Cover_Cash-Cover_Debt)/Cover_Shares,"n/m") | E29: =IFERROR((E28+Cover_Cash-Cover_Debt)/Cover_Shares,"n/m")
A31: METHOD 2 — EXIT MULTIPLE ON FY2030E EBITDA
B32: FY2030E enterprise value at exit multiple ($mm) | C32: =C13*C22 | D32: =D13*D22 | E32: =E13*E22
B33: Enterprise value today ($mm) | C33: =C25+C32/(1+C20)^4.5 | D33: =D25+D32/(1+D20)^4.5 | E33: =E25+E32/(1+E20)^4.5
B34: Implied share price — exit multiple | C34: =IFERROR((C33+Cover_Cash-Cover_Debt)/Cover_Shares,"n/m") | D34: =IFERROR((D33+Cover_Cash-Cover_Debt)/Cover_Shares,"n/m") | E34: =IFERROR((E33+Cover_Cash-Cover_Debt)/Cover_Shares,"n/m")
A36: BLENDED TARGET, UPSIDE AND PROBABILITY WEIGHTING
B37: Blended target (average of the two methods) | C37: =IFERROR(AVERAGE(C29,C34),"n/m") | D37: =IFERROR(AVERAGE(D29,D34),"n/m") | E37: =IFERROR(AVERAGE(E29,E34),"n/m")
B38: Upside / (downside) vs. current price | C38: =IFERROR(C37/Cover_Price-1,"n/m") | D38: =IFERROR(D37/Cover_Price-1,"n/m") | E38: =IFERROR(E37/Cover_Price-1,"n/m")
B39: Scenario probability weight | C39: 0.3 | D39: 0.5 | E39: 0.2 | G39: The model's own judgment, stated explicitly rather than buried. Weighted toward Base because FY2026E is effectively locked by guidance and three quarters of actuals. The Bear weight EXCEEDS the Bull weight deliberately: AI substitution of a seat-based creative franchise is a real risk, it has not been falsified, and the H2 FY26 ARR deceleration is the first hard evidence either way.
B40: PROBABILITY-WEIGHTED TARGET PRICE | C40: =SUMPRODUCT(C37:E37,C39:E39)
B41: Upside / (downside) to probability-weighted target | C41: =IFERROR(C40/Cover_Price-1,"n/m")
B42: Check: scenario weights sum to 100% | C42: =SUM(C39:E39)
B44: WHICH SCENARIO IS THE MARKET PRICING? At $291.52 the stock sits between the Bear and Base outcomes, much closer to Bear than the headline multiple suggests. The reverse DCF on the DCF & WACC tab makes the same point without any scenario machinery: the current price implies a perpetual growth rate far below inflation. For today's price to be FAIR rather than cheap, one of two things must be true — either the FY2026E-FY2030E revenue CAGR is nearer the Bear 3.5% than the guided trajectory, or the FY2030E operating margin settles closer to 29% than 37% because generative-AI inference cost and permanent customer acquisition spend are structural rather than transitional. Both are legitimate views. Neither is what Adobe's own reported numbers show as of Q2 FY2026, which is the substance of the disagreement.

Sheet Sensitivity
A2: IMPLIED SHARE PRICE — WACC x TERMINAL GROWTH (Base-case cash flows)
B3: Rebuilds the DCF arithmetic inside each cell rather than using a what-if Data Table, so the grid is live and portable across Excel and LibreOffice. Both axes are cell references, so editing an axis label genuinely changes the grid.
B5: WACC DOWN / terminal growth ACROSS | C5: 0.01 | D5: 0.018 | E5: 0.025 | F5: 0.03 | G5: 0.035 | H5: 0.04
