Workbook

Sheet Cover
B2: CIRCLE INTERNET GROUP, INC.
B3: NYSE: CRCL | Equity Research Model v2 — Fundamental + Technical
B4: Prepared for informational/educational purposes — not investment advice
B5: Model date: | C5: 2026-08-24
B6: Market data as of: | C6: Aug 21, 2026 close
A8: MARKET SNAPSHOT
B9: Last price (Aug 21, 2026 close) | C9: 87.98 | E9: stockanalysis.com — up 5.2% that session
B10: 52-week high / low | C10: $159.47 / $49.90 | E10: stockanalysis.com
B11: Basic shares outstanding (mm) | C11: 253.88 | E11: stockanalysis.com, Aug 21 2026
B12: Weighted-avg diluted shares, Q2'26 actual (mm) | C12: 268.6 | E12: Circle Q2 2026 press release — includes dilutive RSUs/options
B13: Market capitalization ($mm) | C13: =Cover_Price*Cover_Shares -> 22336.362 | E13: Formula: price x basic shares out
B14: Cash & equivalents ($mm) | C14: 1730 | E14: Circle Q2 2026 press release, 6/30/26 balance sheet
B15: Total debt ($mm) | C15: 0 | E15: Convertible notes ($36.8mm) retired by Q2'26 — no meaningful debt
B16: Net cash ($mm) | C16: =C14-C15 -> 1730 | E16: Formula: cash - debt
A18: DASHBOARD — CURRENT PRICE VS. SCENARIO TARGETS
C19: Bear | D19: Base | E19: Bull
B20: Method 1 — exit multiple | C20: =Valuation!C114 -> 13.508839 | D20: =Valuation!D114 -> 38.004203 | E20: =Valuation!E114 -> 108.20587
B21: Method 2 — DCF | C21: =Valuation!C115 -> 18.983177 | D21: =Valuation!D115 -> 37.138011 | E21: =Valuation!E115 -> 66.529578
B22: Blended (avg of Method 1 & 2) | C22: =Valuation!C116 -> 16.246008 | D22: =Valuation!D116 -> 37.571107 | E22: =Valuation!E116 -> 87.367724
B23: Current price | C23: =Cover_Price -> 87.98 | D23: =Cover_Price -> 87.98 | E23: =Cover_Price -> 87.98
B24: Upside / (downside) to blended | C24: =IFERROR(C22/C23-1,"-") -> -0.81534431 | D24: =IFERROR(D22/D23-1,"-") -> -0.57295855 | E24: =IFERROR(E22/E23-1,"-") -> -0.0069592631
B25: Street consensus target (reference) | C25: =Valuation!$E$27 -> 105 | D25: =Valuation!$E$27 -> 105 | E25: =Valuation!$E$27 -> 105
B26: Probability-weighted target (25/50/25 Bear/Base/Bull) | C26: =Valuation!$C$121 -> 44.688986
B28: What the market appears to be pricing: at the current price, the stock sits above this model's Bear and Base blended targets and close to the Bull-case Method 1 output — i.e. the market looks like it's underwriting something closer to the Bull scenario (circulation growth re-accelerating, RLDC margin holding or improving, and a market multiple in the low-to-mid teens) than this model's Base case. See the Valuation tab for the full walk.
B30: Key drivers (Base case, FY2026E):
B31: USDC circulation, EOP ($bn) | C31: ='Income Statement'!$C$37 -> 90.36
B32: Reserve yield | C32: ='Income Statement'!$C$39 -> 0.035
B33: RLDC margin (co. defn.) | C33: ='Income Statement'!$C$46 -> 0.425
B34: Adj. EBITDA ($mm) | C34: ='Income Statement'!$C$50 -> 790.59625
B36: Biggest risks: Fed rate path (reserve yield), Open USD distribution-economics threat, USDC share loss to USDT/competitors, GENIUS Act implementation. Biggest catalysts: FOMC meetings (Sep 15-16, Oct 27-28, Dec 8-9), Q3'26 earnings, GENIUS Act NPRM comment close (Oct 19). See Thesis & Key Debates and Catalysts & Timeline tabs.
B38: What has to be true for Base case: circulation growth stabilizes around 18-20%/yr (below management's 40% long-run target but above a full Open-USD-driven collapse); RLDC margin holds near the low end of FY26 guidance (42.5%) even as competitive pressure mounts; no major renegotiation of the Coinbase distribution deal. What has to additionally be true for Bull: circulation growth re-accelerates toward management's stated 40% target; RLDC margin actually IMPROVES to 45-46% (Circle successfully defends/improves distribution economics against Open USD, not just holds them); Other Revenue (CPN/Arc/USYC) keeps compounding at ~45%/yr.
B53: Tabs: Cover | Thesis & Key Debates | Historical Financials | Assumptions | Rate & Circulation Sensitivity | Income Statement | Balance Sheet | Cash Flow Statement | SBC & Dilution Schedule | Valuation | Competitive & Distrib Risks | Appendix - Technical Data | Catalysts & Timeline | Sources & Notes
B54: Color key: Blue = hardcoded input. Black = formula. Yellow fill = editable scenario assumption. Bear/Base/Bull rows are colored red/blue/green throughout for quick scanning.
B56: DISCLAIMER: Built from public secondary and primary sources (Circle press releases, SEC-adjacent filings, FRED, financial media) as of the model date above, not a live market data terminal. Every hardcoded figure is sourced on the Sources & Notes tab. Bear/Base/Bull scenario assumptions beyond the current guided fiscal year are this model's own illustrative construction, not sell-side consensus by case — see Assumptions tab. Nothing here is investment, legal, or tax advice.

Sheet Thesis & Key Debates
A2: INVESTMENT THESIS (SUMMARY)
B4: Circle earns reserve income on the short-duration Treasuries and repo backing USDC in circulation, shares roughly 60% of that reserve income with Coinbase and other distribution partners, and keeps the rest as RLDC (reserve income less distribution costs) plus a small and growing 'other revenue' line (CPN, Arc, USYC). The stock is simultaneously a rates-sensitive earnings stream (reserve yield falls as the Fed cuts) and a stablecoin-adoption growth story (USDC circulation, management's stated 40% CAGR through-cycle target) — those two forces currently point in opposite directions for near-term reserve income, and the market is genuinely unsettled about which dominates (see analyst price-target dispersion on the Valuation tab: Morgan Stanley $37 vs. Canaccord $130).
A6: BULL CASE
B8: • USDC circulation keeps compounding as stablecoins get regulatory legitimacy (GENIUS Act) and institutional rails (Arc, CPN) — management's own long-run target is 40% CAGR, well above the ~19% most recently disclosed YoY growth, so there's real room for the growth story to reassert.
B9: • Other revenue (CPN, Arc, USYC, ARC token economics) is a small but fast-growing diversification away from pure rate-sensitivity — FY26 guidance for this line was raised meaningfully (to $310-330mm from $150-170mm) mid-year, and a $222mm ARC token sale closed in Q1'26.
B10: • RLDC margin guidance was raised (to 41.7-43.7% from 38-40%) alongside Q2'26 results — a signal management sees room to hold or improve distribution economics, not just defend them.
B11: • Net cash-rich, no meaningful debt — balance sheet risk is low, and any capital return or M&A optionality is unencumbered.
A13: BEAR CASE
B15: • Reserve income is the overwhelming majority of revenue and is mechanically exposed to Fed rate cuts — every 100bp of cuts strips a large, roughly linear chunk of gross reserve income absent offsetting circulation growth (see Rate & Circulation Sensitivity tab).
B16: • Open USD (Stripe/Coinbase/Visa/Mastercard/BlackRock-backed consortium, announced Jun 30 2026) is the most credible structural threat to USDC's economics since Circle's inception per CoinShares — its model redirects the majority of reserve income to distribution partners, which could force Circle into less favorable terms even if USDC itself doesn't lose material share.
B17: • USDC's stablecoin market share has fallen from a peak of roughly 35% to about 23% as of Aug 2026, while USDT holds roughly 59% — Circle is not the dominant player in its own category.
B18: • Revenue growth has decelerated sharply and consistently: +77% (Q4'25) -> +20% (Q1'26) -> +7% (Q2'26) YoY, even as circulation kept growing, because yield compression outpaced it.
B19: • No confirmed capital-return program (buyback/dividend) and continued net share dilution from stock-based comp (weighted-avg diluted shares rose from 267.9mm to 268.6mm quarter-over-quarter) work against per-share value creation even if the underlying business grows.
A21: KEY DEBATES TO WATCH
B23: • Fed path vs. circulation growth: does USDC circulation growth (bull case assumes acceleration toward management's 40% target; this model's base case assumes a more modest ~20%) outrun further reserve-yield compression, or does yield compression win?
B24: • Open USD: is it, per Coindesk's Aug 3 2026 reporting, mostly 'hedging' by nominal backers (Visa/Mastercard/Coinbase all still publicly supporting USDC too) with no committed volume shift yet — or an early signal of a structural distribution-economics renegotiation to come?
B25: • GENIUS Act implementation: the Treasury NPRM comment period runs through Oct 19 2026 — the final rule could tighten (compliance cost headwind) or formalize/entrench Circle's position (moat) depending on outcome.
B26: • Whether the market is pricing CRCL as a rate-sensitive financial (bear framing) or a stablecoin-infrastructure growth compounder (bull framing) — the >3x spread in sell-side price targets suggests this is not yet a settled debate.

Sheet Historical Financials
A2: CRCL — HISTORICAL FINANCIALS ($mm unless noted)
B3: Source: Circle press releases (Q4'25, Q1'26, Q2'26 earnings releases, primary source PDF for Q2'26); FY24/FY25 per FY2025 10-K / Q4'25 release. Reserve income shown is a derived residual (Total Rev - Other Rev) except where noted as the company's own disclosed figure.
B5: Line item | C5: FY2024A | D5: FY2025A | E5: Q4'25A | F5: Q1'26A | G5: Q2'26A
B6: Total revenue & reserve income | C6: 1646 | D6: 2700 | E6: 770 | F6: 694 | G6: 701 | H6: FY24 implied from FY25 +64% YoY disclosure
B7: Other revenue | C7: 15 | D7: 110 | E7: 37 | F7: 42 | G7: 33.3 | H7: Q2'26 = 701 - 667.7 reserve income (Circle's own reported figure, primary source)
B8: Reserve income | C8: =C6-C7 -> 1631 | D8: =D6-D7 -> 2590 | E8: =E6-E7 -> 733 | F8: =F6-F7 -> 652 | G8: 667.7 | H8: Q2'26 = Circle's own disclosed figure ($667.733mm); earlier periods derived as Total-Other
B9: Distribution, transaction & other costs | C9: 1010 | D9: 1662 | E9: 461 | F9: 407 | G9: 410.4 | H9: Q2'26 = Circle's own disclosed figure ($410.414mm)
B10: RLDC (company definition: Total Rev - Dist. Costs) | C10: =C6-C9 -> 636 | D10: =D6-D9 -> 1038 | E10: =E6-E9 -> 309 | F10: =F6-F9 -> 287 | G10: =G6-G9 -> 290.6 | H10: Circle's own definition nets distribution costs against TOTAL revenue, not just reserve income — see reconciliation note below
B11: RLDC margin (co. defn., % of Total Revenue) | C11: =IFERROR(C10/C6,"-") -> 0.38639125 | D11: =IFERROR(D10/D6,"-") -> 0.38444444 | E11: =IFERROR(E10/E6,"-") -> 0.4012987 | F11: =IFERROR(F10/F6,"-") -> 0.41354467 | G11: =IFERROR(G10/G6,"-") -> 0.41455064 | H11: Circle's own reported/guided metric — Q2'26 actual 41%, FY26 guided 41.7-43.7%
B12: Distribution cost ratio (% of reserve income, analytical) | C12: =IFERROR(C9/C8,"-") -> 0.61925199 | D12: =IFERROR(D9/D8,"-") -> 0.64169884 | E12: =IFERROR(E9/E8,"-") -> 0.62892224 | F12: =IFERROR(F9/F8,"-") -> 0.62423313 | G12: =IFERROR(G9/G8,"-") -> 0.6146473 | H12: This model's own analytical driver for the Rate & Circulation Sensitivity grid — differs from the company's RLDC margin definition above by construction
B13: Net income / (loss) | C13: 157 | D13: -70 | E13: 133 | F13: 55 | G13: 48 | H13: FY25 net loss driven by ~$424mm one-time IPO-vesting stock comp charge
B14: Adjusted EBITDA | D14: 582 | E14: 167 | F14: 151 | G14: 143
B15: Adj. EBITDA margin (% of total revenue) | C15: =IF(ISBLANK(C14),"n/a",IFERROR(C14/C6,"-")) -> n/a | D15: =IF(ISBLANK(D14),"n/a",IFERROR(D14/D6,"-")) -> 0.21555556 | E15: =IF(ISBLANK(E14),"n/a",IFERROR(E14/E6,"-")) -> 0.21688312 | F15: =IF(ISBLANK(F14),"n/a",IFERROR(F14/F6,"-")) -> 0.21757925 | G15: =IF(ISBLANK(G14),"n/a",IFERROR(G14/G6,"-")) -> 0.20399429
B16: Stock-based compensation | G16: 53.6 | H16: Q2'26 actual, primary source; ~$61.2mm incl. related payroll taxes
B17: Weighted-avg diluted shares (mm) | F17: 267.9 | G17: 268.6 | H17: Primary source (Q2'26 press release) — higher than basic shares out (253.9mm) because it includes dilutive RSUs/options; see SBC & Dilution Schedule tab for the forward walk
B19: USDC circulation, end of period ($bn) | C19: 43.9 | D19: 75.3 | E19: 75.3 | F19: 77 | G19: 73.3 | H19: FY24 implied from FY25 +72% YoY disclosure; Q2'26 down sequentially from Q1'26
B20: USDC circulation YoY growth (as disclosed) | D20: 0.72 | E20: 0.72 | F20: 0.28 | G20: 0.19
B21: Total revenue YoY growth (as disclosed) | D21: 0.64 | E21: 0.77 | F21: 0.2 | G21: 0.07
B23: Implied annualized reserve yield (reserve income x4 / EOP USDC) | E23: =IFERROR(E8*4/E19,"-") -> 38.937583 | F23: =IFERROR(F8*4/F19,"-") -> 33.87013 | G23: =IFERROR(G8*4/G19,"-") -> 36.436562 | H23: Approximation — uses EOP circulation as a proxy for average circulation (see limitation note below; Income Statement tab uses a 2-quarter average instead)
B25: RLDC MARGIN RECONCILIATION CHECK (satisfies the 'add basic checks' review item): Q2'26 actual — Circle's own RLDC margin (41%) = (Total Rev $701mm - Dist. Costs $410.4mm) / Total Rev $701mm = 41.4%, rounds to 41%. This model's analytical 'distribution cost ratio' (61.5%) is a DIFFERENT metric — distribution costs as a share of reserve income only ($410.4mm/$667.7mm) — used because it plugs directly into the Fed-rate x circulation sensitivity grid on the next tab. Both are correct for their own purpose; they are not interchangeable and this model uses both, labeled, rather than picking one.
B27: Read-through: revenue growth decelerated from +77% (Q4'25) to +20% (Q1'26) to +7% (Q2'26) YoY even as USDC circulation kept growing, because the reserve yield compressed as the Fed cut rates. Management responded by RAISING RLDC margin guidance (to 41.7-43.7% from 38-40%) and Other Revenue guidance (to $310-330mm from $150-170mm) alongside Q2'26 results — the company itself is signaling that non-reserve-income levers are doing more work. See Income Statement tab for the forward build.
A30: BALANCE SHEET & CASH FLOW ANCHOR (Q2'26A ACTUAL — PRIMARY SOURCE: 10-Q FOR PERIOD ENDED JUNE 30, 2026, FILED AUG 5 2026)
B31: New in v3: real balance-sheet and cash-flow actuals, pulled via SEC EDGAR XBRL (data.sec.gov/api/xbrl/companyconcept) and the underlying 10-Q for line items not separately XBRL-tagged (e.g. the corporate-vs-reserve cash split). These anchor the Balance Sheet, Cash Flow Statement, and SBC & Dilution Schedule tabs' FY2026E opening balances. Circle's balance sheet is dominated by a dollar-for-dollar USDC reserve/circulation pass-through (~$74bn of the ~$77bn in total assets) that has no bearing on equity value — this model separates that pass-through from the much smaller 'corporate' balance sheet that actually drives per-share value, rather than letting the pass-through swamp the analysis.
B34: Line item | C34: Q2'26A ($mm) | D34: Source / derivation
B35: Corporate cash & equivalents (non-reserve) | C35: 1730.126 | D35: 10-Q balance sheet, 6/30/26 — excludes reserve/segregated stablecoin cash
B36: Other corporate assets, net (PP&E + other — reconciling combination) | C36: 2507.79 | D36: Derived: Total assets - modeled reserve assets - corporate cash (reconciling-plug convention). Includes the real 10-Q's $889.311mm 'segregated stablecoin cash' bucket plus a ~$122.9mm reserve-over-deposits buffer — both folded in here, NOT into the pass-through reserve line below, so that line can be modeled as backing circulation exactly 1:1 (see note there) without breaking the balance check. Granular PP&E/other itemization not separately sourced.
B37: USDC reserve assets (pass-through, modeled as backing circulation 1:1) | C37: 72927.544 | D37: Set equal to the circulation liability below (10-Q's actual reserve assets were $74,050.483mm incl. segregated stablecoin cash — the ~$1,122.9mm difference is folded into 'other corporate assets' above) so the forward model's reserve-assets and circulation-liability lines move in lockstep and the balance check ties out by construction, not by coincidence
B38: TOTAL ASSETS | C38: =C35+C36+C37 -> 77165.46 | D38: 10-Q reported: $77,165.460mm — formula cross-check should match exactly
B40: Other corporate liabilities (accrued exp., deferred rev., etc.) | C40: 727.941 | D40: Derived: Total liabilities - stablecoin deposits (reconciling-plug convention)
B41: Total debt / borrowings | C41: 0 | D41: 10-Q: none outstanding — convertible notes fully converted during H1'26
B42: USDC in circulation / stablecoin deposits (pass-through liability) | C42: 72927.544 | D42: 10-Q: 'deposits from stablecoin holders' — backs the reserve assets ~1:1
B43: TOTAL LIABILITIES | C43: =C40+C42 -> 73655.485 | D43: 10-Q reported: $73,655.485mm — formula cross-check should match exactly
B45: TOTAL STOCKHOLDERS' EQUITY | C45: 3509.975 | D45: 10-Q reported — also = Total assets - Total liabilities exactly (no plug needed)
B47: H1'26 (6mo) depreciation & amortization | C47: 56.663
B48: H1'26 (6mo) stock-based compensation | C48: 105.435
B49: H1'26 (6mo) net cash from operating activities | C49: 538.505
B50: H1'26 (6mo) capex (purchase of long-lived assets) | C50: 10.389 | D50: Real capex only — excludes ~$47mm of H1'26 investing outflows tied to the reserve/securities portfolio, which is pass-through and excluded from this model's corporate cash-flow build
B52: Cross-checks used to derive H1'26 revenue for the SBC-and-D&A-as-%-of-revenue ratios used on the Assumptions tab: H1'26 revenue = Q1'26 $694mm + Q2'26 $701mm = $1,395mm. SBC/revenue = $105.4mm/$1,395mm = 7.6%; D&A/revenue = $56.7mm/$1,395mm = 4.1%; capex/revenue = $10.4mm/$1,395mm = 0.7%. FY2025A SBC/revenue (20.9%) is NOT used as the forward anchor — it's inflated by a one-time ~$424mm IPO-vesting charge (see Net income note above) that is not representative of a steady-state run-rate.

Sheet Assumptions
A2: SCENARIO ASSUMPTIONS — CHANGE ANY YELLOW CELL TO RE-RUN THE MODEL
B3: Near-term (FY2026E) values are anchored to Circle's own guidance where available (Other Revenue $310-330mm, RLDC margin 41.7-43.7%, Adj. Opex $570-585mm). Bear/Base/Bull divergence beyond that is this model's own illustrative construction — no third-party sell-side estimates were found broken out by scenario for circulation growth or RLDC margin specifically. Treat the case spread as a framework for stress-testing your own view, not a consensus range.
B6: Driver / Case | C6: FY2026E | D6: FY2027E | E6: FY2028E
B7: USDC avg circulation YoY growth (vs. prior year)
B8: Bear | C8: 0.1 | D8: 0.08 | E8: 0.06
B9: Base | C9: 0.2 | D9: 0.18 | E9: 0.16
B10: Bull | C10: 0.35 | D10: 0.32 | E10: 0.3
B12: Reserve yield (annualized)
B13: Bear | C13: 0.033 | D13: 0.029 | E13: 0.025
B14: Base | C14: 0.035 | D14: 0.032 | E14: 0.029
B15: Bull | C15: 0.036 | D15: 0.035 | E15: 0.033
B17: RLDC margin (co. definition, % of Total Revenue)
B18: Bear | C18: 0.4 | D18: 0.39 | E18: 0.38
B19: Base | C19: 0.425 | D19: 0.425 | E19: 0.425
B20: Bull | C20: 0.45 | D20: 0.455 | E20: 0.46
B22: v3: Other Revenue is now split into Arc (Circle's L1 chain — presale/milestone revenue recognition per Q2'26 commentary) and Other Products (CPN + USYC + custody/tokenization + misc), instead of one lump line, so 'what has to grow' is answerable. FY26E figures ($180mm Arc / $140mm Other Products = $320mm) are anchored to Q2'26 earnings-call color: Arc's FY26 revenue-recognition guidance of ~$180mm (upon product milestones, ~75% of 2026 milestones) and the remaining $130-150mm FY26 guide attributed to other products. FY27E-FY28E splits are this model's own construction, calibrated so each case's TOTAL still sums to the same Bear/Base/Bull totals used in v2.1 ($352/$400/$464mm FY27E, $387/$500/$673mm FY28E) — the split changes what you can say about the number, not the number itself.
B26: Arc revenue ($mm, FY26E fixed at guidance; growth thereafter)
B27: Bear | C27: 180 | D27: 190 | E27: 205
B28: Base | C28: 180 | D28: 230 | E28: 300
B29: Bull | C29: 180 | D29: 290 | E29: 430
B31: Other products revenue ($mm — CPN + USYC + custody/tokenization; FY26E at guidance)
B32: Bear | C32: 140 | D32: 162 | E32: 182
B33: Base | C33: 140 | D33: 170 | E33: 200
B34: Bull | C34: 140 | D34: 174 | E34: 243
B36: Implied FY26E-FY28E Arc revenue CAGR | C36: =IFERROR((E27/C27)^(1/2)-1,"-") -> 0.067187373 | D36: =IFERROR((E28/C28)^(1/2)-1,"-") -> 0.29099445 | E36: =IFERROR((E29/C29)^(1/2)-1,"-") -> 0.54560308
B37: Implied FY26E-FY28E Other Products revenue CAGR | C37: =IFERROR((E32/C32)^(1/2)-1,"-") -> 0.14017543 | D37: =IFERROR((E33/C33)^(1/2)-1,"-") -> 0.19522861 | E37: =IFERROR((E34/C34)^(1/2)-1,"-") -> 0.3174651
B38: Arc is this model's biggest Bear/Bull swing factor (Bear ~7% CAGR vs. Bull ~55% CAGR) because it's presale/milestone-based, not a running rate yet — mainnet launches Sept 16, 2026 with BlackRock and DTCC named as participants per the Q2'26 call, so the Bull case requires that launch to translate into sustained third-party issuance/RWA volume, not just a one-time presale credit. Other Products is better-grounded in an actual trend: CPN's trailing-30-day annualized TPV grew 130% in the ~6 weeks after Q2'26 earnings (to ~$23bn as of Jul 31, 2026) and USYC AUM grew 10x YoY to >$3bn — real momentum, though TPV/AUM are volume metrics, not disclosed revenue, so the $mm figures above are still this model's own translation of that volume growth into a revenue estimate, not a disclosed number.
B41: Adjusted operating expenses ($mm)
B42: Bear | C42: 577.5 | D42: 646.8 | E42: 724.4
B43: Base | C43: 577.5 | D43: 623.7 | E43: 673.6
B44: Bull | C44: 577.5 | D44: 606.4 | E44: 636.7
B46: Diluted share count growth (net dilution, YoY)
B47: Bear | C47: 0.03 | D47: 0.03 | E47: 0.03
B48: Base | C48: 0.02 | D48: 0.02 | E48: 0.02
B49: Bull | C49: 0.01 | D49: 0.01 | E49: 0.01
B51: Stock-based compensation (% of Total Revenue)
B52: Bear | C52: 0.085 | D52: 0.085 | E52: 0.085
B53: Base | C53: 0.075 | D53: 0.07 | E53: 0.065
B54: Bull | C54: 0.07 | D54: 0.06 | E54: 0.05
B56: H1'26A actual: SBC/revenue = 7.6% ($105.4mm / $1,395mm) — see Historical Financials BS/CF anchor. Base case anchors near this actual, then declines modestly as revenue outgrows a roughly fixed equity-comp pool (operating leverage); Bear holds flat since a weaker revenue denominator keeps the ratio elevated.
...

Sheet Rate & Circulation Sensitivity
A2: RESERVE INCOME MODEL & FED RATE SENSITIVITY
B3: Circle's revenue is ~95%+ reserve/interest income on USDC-backing Treasuries and repo — this is the single most important driver in the model. Base-case inputs below are pulled from the Assumptions tab (FY26E column) so this grid and the Income Statement tab always agree.
B6: Base USDC avg circulation ($bn) | D6: =Assumptions!$C$81 -> 75.3
B7: Base annualized reserve yield (Base case, FY26E) | D7: =Assumptions!$C$14 -> 0.035
B8: Distribution cost ratio (% of reserve income, Q2'26 actual) | D8: ='Historical Financials'!$G$12 -> 0.6146473
B9: Other revenue ($mm, Base case FY26E = Arc + Other Products) | D9: =Assumptions!$C$28+Assumptions!$C$33 -> 320
B10: Adjusted operating expenses ($mm, Base case FY26E) | D10: =Assumptions!$C$43 -> 577.5
A12: GRID 1 — ANNUALIZED RESERVE INCOME ($mm)
B13: Fed funds change (bps) ↓ / USDC circulation YoY growth → | C13: -0.1 | D13: 0 | E13: 0.1 | F13: 0.2 | G13: 0.3 | H13: 0.4
B14: -100 bps | C14: =(D7+-100/10000)*(D6*(1+C$13))*1000 -> 1694.25 | D14: =(D7+-100/10000)*(D6*(1+D$13))*1000 -> 1882.5 | E14: =(D7+-100/10000)*(D6*(1+E$13))*1000 -> 2070.75 | F14: =(D7+-100/10000)*(D6*(1+F$13))*1000 -> 2259 | G14: =(D7+-100/10000)*(D6*(1+G$13))*1000 -> 2447.25 | H14: =(D7+-100/10000)*(D6*(1+H$13))*1000 -> 2635.5
B15: -75 bps | C15: =(D7+-75/10000)*(D6*(1+C$13))*1000 -> 1863.675 | D15: =(D7+-75/10000)*(D6*(1+D$13))*1000 -> 2070.75 | E15: =(D7+-75/10000)*(D6*(1+E$13))*1000 -> 2277.825 | F15: =(D7+-75/10000)*(D6*(1+F$13))*1000 -> 2484.9 | G15: =(D7+-75/10000)*(D6*(1+G$13))*1000 -> 2691.975 | H15: =(D7+-75/10000)*(D6*(1+H$13))*1000 -> 2899.05
B16: -50 bps | C16: =(D7+-50/10000)*(D6*(1+C$13))*1000 -> 2033.1 | D16: =(D7+-50/10000)*(D6*(1+D$13))*1000 -> 2259 | E16: =(D7+-50/10000)*(D6*(1+E$13))*1000 -> 2484.9 | F16: =(D7+-50/10000)*(D6*(1+F$13))*1000 -> 2710.8 | G16: =(D7+-50/10000)*(D6*(1+G$13))*1000 -> 2936.7 | H16: =(D7+-50/10000)*(D6*(1+H$13))*1000 -> 3162.6
B17: -25 bps | C17: =(D7+-25/10000)*(D6*(1+C$13))*1000 -> 2202.525 | D17: =(D7+-25/10000)*(D6*(1+D$13))*1000 -> 2447.25 | E17: =(D7+-25/10000)*(D6*(1+E$13))*1000 -> 2691.975 | F17: =(D7+-25/10000)*(D6*(1+F$13))*1000 -> 2936.7 | G17: =(D7+-25/10000)*(D6*(1+G$13))*1000 -> 3181.425 | H17: =(D7+-25/10000)*(D6*(1+H$13))*1000 -> 3426.15
B18: +0 bps | C18: =(D7+0/10000)*(D6*(1+C$13))*1000 -> 2371.95 | D18: =(D7+0/10000)*(D6*(1+D$13))*1000 -> 2635.5 | E18: =(D7+0/10000)*(D6*(1+E$13))*1000 -> 2899.05 | F18: =(D7+0/10000)*(D6*(1+F$13))*1000 -> 3162.6 | G18: =(D7+0/10000)*(D6*(1+G$13))*1000 -> 3426.15 | H18: =(D7+0/10000)*(D6*(1+H$13))*1000 -> 3689.7
B19: +25 bps | C19: =(D7+25/10000)*(D6*(1+C$13))*1000 -> 2541.375 | D19: =(D7+25/10000)*(D6*(1+D$13))*1000 -> 2823.75 | E19: =(D7+25/10000)*(D6*(1+E$13))*1000 -> 3106.125 | F19: =(D7+25/10000)*(D6*(1+F$13))*1000 -> 3388.5 | G19: =(D7+25/10000)*(D6*(1+G$13))*1000 -> 3670.875 | H19: =(D7+25/10000)*(D6*(1+H$13))*1000 -> 3953.25
A21: GRID 2 — IMPLIED ADJ. EBITDA ($mm), ANALYTICAL DIST. RATIO METHOD
C22: -0.1 | D22: 0 | E22: 0.1 | F22: 0.2 | G22: 0.3 | H22: 0.4
B23: -100 bps | C23: =C14*(1-D8)+D9-D10 -> 395.38382 | D23: =D14*(1-D8)+D9-D10 -> 467.92646 | E23: =E14*(1-D8)+D9-D10 -> 540.46911 | F23: =F14*(1-D8)+D9-D10 -> 613.01176 | G23: =G14*(1-D8)+D9-D10 -> 685.5544 | H23: =H14*(1-D8)+D9-D10 -> 758.09705
B24: -75 bps | C24: =C15*(1-D8)+D9-D10 -> 460.6722 | D24: =D15*(1-D8)+D9-D10 -> 540.46911 | E24: =E15*(1-D8)+D9-D10 -> 620.26602 | F24: =F15*(1-D8)+D9-D10 -> 700.06293 | G24: =G15*(1-D8)+D9-D10 -> 779.85984 | H24: =H15*(1-D8)+D9-D10 -> 859.65675
B25: -50 bps | C25: =C16*(1-D8)+D9-D10 -> 525.96058 | D25: =D16*(1-D8)+D9-D10 -> 613.01176 | E25: =E16*(1-D8)+D9-D10 -> 700.06293 | F25: =F16*(1-D8)+D9-D10 -> 787.11411 | G25: =G16*(1-D8)+D9-D10 -> 874.16528 | H25: =H16*(1-D8)+D9-D10 -> 961.21646
B26: -25 bps | C26: =C17*(1-D8)+D9-D10 -> 591.24896 | D26: =D17*(1-D8)+D9-D10 -> 685.5544 | E26: =E17*(1-D8)+D9-D10 -> 779.85984 | F26: =F17*(1-D8)+D9-D10 -> 874.16528 | G26: =G17*(1-D8)+D9-D10 -> 968.47072 | H26: =H17*(1-D8)+D9-D10 -> 1062.7762
B27: +0 bps | C27: =C18*(1-D8)+D9-D10 -> 656.53734 | D27: =D18*(1-D8)+D9-D10 -> 758.09705 | E27: =E18*(1-D8)+D9-D10 -> 859.65675 | F27: =F18*(1-D8)+D9-D10 -> 961.21646 | G27: =G18*(1-D8)+D9-D10 -> 1062.7762 | H27: =H18*(1-D8)+D9-D10 -> 1164.3359
B28: +25 bps | C28: =C19*(1-D8)+D9-D10 -> 721.82573 | D28: =D19*(1-D8)+D9-D10 -> 830.6397 | E28: =E19*(1-D8)+D9-D10 -> 939.45367 | F28: =F19*(1-D8)+D9-D10 -> 1048.2676 | G28: =G19*(1-D8)+D9-D10 -> 1157.0816 | H28: =H19*(1-D8)+D9-D10 -> 1265.8956
B30: Cross-check: independent analyst estimates (Dragonfly's Omar Kanji, circulated Aug 2026) pegged a 100bp Fed cut at ~$618mm of gross reserve-income impact (~23% of then-current revenue) absent offsetting USDC growth. The 0%-growth / -100bps cell in Grid 1 above is this model's independently-derived analogue — compare the two. Grid 2 uses the analytical distribution-ratio method (see Historical Financials tab reconciliation note); the Income Statement tab uses Circle's own RLDC-margin convention instead, which will produce slightly different EBITDA figures by construction — both are shown, labeled, rather than picking one.
B32: Model limitation: assumes roughly 1:1 pass-through of Fed rate changes to reserve yield and a constant distribution-cost ratio within this grid — in reality both the yield curve (reserves are short-duration T-bills/repo, not fed-funds-linked overnight instruments) and the Coinbase distribution formula (tiered by where USDC balances sit) are more complex. Cross-check: the effective fed funds rate was 3.63% as of Aug 20, 2026 (FRED) vs. this model's Base-case FY26E reserve yield assumption of 3.5% — close, consistent with near-1:1 pass-through, though not exact.

Sheet Income Statement
A2: INCOME STATEMENT — FY2026E-FY2028E, BY SCENARIO
B3: v3: a real income statement (Revenue -> Distribution costs -> RLDC -> Opex -> D&A -> EBIT -> Interest -> EBT -> Taxes -> Net Income), replacing v2.1's jump straight from EBITDA to an 'illustrative FCF proxy.' Revenue is now built explicitly (circulation bridge + Arc + Other Products, instead of one lump Other Revenue line) and D&A/SBC are real expense lines pulled from the SBC & Dilution Schedule tab, not omitted. See that tab and the Balance Sheet / Cash Flow Statement tabs for the rest of the 3-statement build.
B6: BEAR CASE
C7: FY2026E | D7: FY2027E | E7: FY2028E
B8: USDC circulation, end of period ($bn) | C8: =Assumptions!$C$81*(1+Assumptions!$C$8) -> 82.83 | D8: =C8*(1+Assumptions!$D$8) -> 89.4564 | E8: =D8*(1+Assumptions!$E$8) -> 94.823784
B9: USDC avg circulation ($bn, avg of beg./end. EOP) | C9: =(Assumptions!$C$81+C8)/2 -> 79.065 | D9: =(C8+D8)/2 -> 86.1432 | E9: =(D8+E8)/2 -> 92.140092
B10: Reserve yield (annualized) | C10: =Assumptions!$C$13 -> 0.033 | D10: =Assumptions!$D$13 -> 0.029 | E10: =Assumptions!$E$13 -> 0.025
B11: Reserve income ($mm) | C11: =C9*1000*C10 -> 2609.145 | D11: =D9*1000*D10 -> 2498.1528 | E11: =E9*1000*E10 -> 2303.5023
B12: Arc revenue ($mm) | C12: =Assumptions!$C$27 -> 180 | D12: =Assumptions!$D$27 -> 190 | E12: =Assumptions!$E$27 -> 205
B13: Other Products revenue ($mm — CPN/USYC/custody) | C13: =Assumptions!$C$32 -> 140 | D13: =Assumptions!$D$32 -> 162 | E13: =Assumptions!$E$32 -> 182
B14: Total Other Revenue ($mm) | C14: =C12+C13 -> 320 | D14: =D12+D13 -> 352 | E14: =E12+E13 -> 387
B15: TOTAL REVENUE ($mm) | C15: =C11+C14 -> 2929.145 | D15: =D11+D14 -> 2850.1528 | E15: =E11+E14 -> 2690.5023
B17: RLDC margin (co. defn., % of Total Revenue) | C17: =Assumptions!$C$18 -> 0.4 | D17: =Assumptions!$D$18 -> 0.39 | E17: =Assumptions!$E$18 -> 0.38
B18: RLDC ($mm) | C18: =C15*C17 -> 1171.658 | D18: =D15*D17 -> 1111.5596 | E18: =E15*E17 -> 1022.3909
B19: Distribution costs ($mm, implied) | C19: =C15-C18 -> 1757.487 | D19: =D15-D18 -> 1738.5932 | E19: =E15-E18 -> 1668.1114
B20: Adjusted operating expenses ($mm) | C20: =Assumptions!$C$42 -> 577.5 | D20: =Assumptions!$D$42 -> 646.8 | E20: =Assumptions!$E$42 -> 724.4
B21: ADJUSTED EBITDA ($mm) | C21: =C18-C20 -> 594.158 | D21: =D18-D20 -> 464.75959 | E21: =E18-E20 -> 297.99087
B22: Adj. EBITDA margin (% of Total Revenue) | C22: =IFERROR(C21/C15,"-") -> 0.20284349 | D22: =IFERROR(D21/D15,"-") -> 0.1630648 | E22: =IFERROR(E21/E15,"-") -> 0.1107566
B23: Less: Depreciation & amortization ($mm) | C23: =C15*Assumptions!$C$59 -> 117.1658 | D23: =D15*Assumptions!$D$59 -> 119.70642 | E23: =E15*Assumptions!$E$59 -> 115.6916
B24: Less: Stock-based compensation ($mm) | C24: ='SBC & Dilution Schedule'!C10 -> 248.97733 | D24: ='SBC & Dilution Schedule'!D10 -> 242.26299 | E24: ='SBC & Dilution Schedule'!E10 -> 228.6927
B25: EBIT ($mm) | C25: =C21-C23-C24 -> 228.01487 | D25: =D21-D23-D24 -> 102.79019 | E25: =E21-E23-E24 -> -46.39342
B26: Plus: Net interest income ($mm) | C26: ='Historical Financials'!$C$35*Assumptions!$C$74 -> 60.55441 | D26: ='Historical Financials'!$C$35*Assumptions!$C$74 -> 60.55441 | E26: ='Historical Financials'!$C$35*Assumptions!$C$74 -> 60.55441 | F26: Computed off the Q2'26A anchor corporate cash balance, held flat across all 3 forecast years — avoids a circular reference to the Balance Sheet's cash roll-forward; see tab-level note above.
B27: EBT ($mm) | C27: =C25+C26 -> 288.56928 | D27: =D25+D26 -> 163.3446 | E27: =E25+E26 -> 14.16099
B28: Less: Income tax expense ($mm) | C28: =MAX(C27,0)*Assumptions!$C$73 -> 60.59955 | D28: =MAX(D27,0)*Assumptions!$C$73 -> 34.302365 | E28: =MAX(E27,0)*Assumptions!$C$73 -> 2.9738078
B29: NET INCOME ($mm) | C29: =C27-C28 -> 227.96974 | D29: =D27-D28 -> 129.04223 | E29: =E27-E28 -> 11.187182
B30: Net income margin (% of Total Revenue) | C30: =IFERROR(C29/C15,"-") -> 0.077828081 | D30: =IFERROR(D29/D15,"-") -> 0.045275548 | E30: =IFERROR(E29/E15,"-") -> 0.0041580272
B31: Diluted shares outstanding (mm) | C31: ='SBC & Dilution Schedule'!C11 -> 276.658 | D31: ='SBC & Dilution Schedule'!D11 -> 284.95774 | E31: ='SBC & Dilution Schedule'!E11 -> 293.50647
B32: Diluted EPS ($) | C32: =IFERROR(C29/C31,"-") -> 0.82401281 | D32: =IFERROR(D29/D31,"-") -> 0.45284691 | E32: =IFERROR(E29/E31,"-") -> 0.038115622
B33: Adj. EBITDA per diluted share ($) | C33: =IFERROR(C21/C31,"-") -> 2.1476263 | D33: =IFERROR(D21/D31,"-") -> 1.6309773 | E33: =IFERROR(E21/E31,"-") -> 1.0152787
B35: BASE CASE
C36: FY2026E | D36: FY2027E | E36: FY2028E
B37: USDC circulation, end of period ($bn) | C37: =Assumptions!$C$81*(1+Assumptions!$C$9) -> 90.36 | D37: =C37*(1+Assumptions!$D$9) -> 106.6248 | E37: =D37*(1+Assumptions!$E$9) -> 123.68477
B38: USDC avg circulation ($bn, avg of beg./end. EOP) | C38: =(Assumptions!$C$81+C37)/2 -> 82.83 | D38: =(C37+D37)/2 -> 98.4924 | E38: =(D37+E37)/2 -> 115.15478
B39: Reserve yield (annualized) | C39: =Assumptions!$C$14 -> 0.035 | D39: =Assumptions!$D$14 -> 0.032 | E39: =Assumptions!$E$14 -> 0.029
B40: Reserve income ($mm) | C40: =C38*1000*C39 -> 2899.05 | D40: =D38*1000*D39 -> 3151.7568 | E40: =E38*1000*E39 -> 3339.4887
B41: Arc revenue ($mm) | C41: =Assumptions!$C$28 -> 180 | D41: =Assumptions!$D$28 -> 230 | E41: =Assumptions!$E$28 -> 300
B42: Other Products revenue ($mm — CPN/USYC/custody) | C42: =Assumptions!$C$33 -> 140 | D42: =Assumptions!$D$33 -> 170 | E42: =Assumptions!$E$33 -> 200
B43: Total Other Revenue ($mm) | C43: =C41+C42 -> 320 | D43: =D41+D42 -> 400 | E43: =E41+E42 -> 500
B44: TOTAL REVENUE ($mm) | C44: =C40+C43 -> 3219.05 | D44: =D40+D43 -> 3551.7568 | E44: =E40+E43 -> 3839.4887
B46: RLDC margin (co. defn., % of Total Revenue) | C46: =Assumptions!$C$19 -> 0.425 | D46: =Assumptions!$D$19 -> 0.425 | E46: =Assumptions!$E$19 -> 0.425
...

Sheet Balance Sheet
A2: BALANCE SHEET — FY2026E-FY2028E, BY SCENARIO
B3: v3: corporate balance sheet (cash, other assets, other liabilities, equity) rolled forward and tied to a real Q2'26A anchor (see Historical Financials). USDC reserve assets and the offsetting USDC-in-circulation liability are shown for completeness (they're what Circle actually reports) but are a dollar-for-dollar pass-through with no bearing on equity value — don't read anything into their scale relative to the much smaller corporate items that actually drive per-share value. BALANCE CHECK row must read exactly 0 for every case/year — verified separately from recalc.py, which only proves formulas evaluate, not that the statements tie out.
B6: BEAR CASE
C7: FY2026E | D7: FY2027E | E7: FY2028E
B8: Cash & equivalents, corporate ($mm) | C8: ='Cash Flow Statement'!C17 -> 2300.8057 | D8: ='Cash Flow Statement'!D17 -> 2769.0161 | E8: ='Cash Flow Statement'!E17 -> 3103.0636
B9: Other corporate assets, net ($mm, PP&E + other — reconciling combination) | C9: ='Historical Financials'!$C$36+'Cash Flow Statement'!C12-'Income Statement'!C23 -> 2414.0574 | D9: =C9+'Cash Flow Statement'!D12-'Income Statement'!D23 -> 2317.1522 | E9: =D9+'Cash Flow Statement'!E12-'Income Statement'!E23 -> 2222.9846
B10: Total corporate assets ($mm) | C10: =C8+C9 -> 4714.8631 | D10: =D8+D9 -> 5086.1683 | E10: =E8+E9 -> 5326.0482
B11: USDC reserve assets (pass-through, $mm) | C11: ='Income Statement'!C8*1000 -> 82830 | D11: ='Income Statement'!D8*1000 -> 89456.4 | E11: ='Income Statement'!E8*1000 -> 94823.784
B12: TOTAL ASSETS ($mm) | C12: =C10+C11 -> 87544.863 | D12: =D10+D11 -> 94542.568 | E12: =E10+E11 -> 100149.83
B14: Other corporate liabilities ($mm, accrued exp., deferred rev., etc.) | C14: ='Historical Financials'!$C$40 -> 727.941 | D14: ='Historical Financials'!$C$40 -> 727.941 | E14: ='Historical Financials'!$C$40 -> 727.941 | F14: Held flat at the Q2'26A anchor — a fuller build would itemize and grow this with revenue/headcount
B15: Total corporate liabilities ($mm, no debt outstanding) | C15: =C14 -> 727.941 | D15: =D14 -> 727.941 | E15: =E14 -> 727.941
B16: USDC in circulation / stablecoin deposits (pass-through, $mm) | C16: =C11 -> 82830 | D16: =D11 -> 89456.4 | E16: =E11 -> 94823.784
B17: TOTAL LIABILITIES ($mm) | C17: =C15+C16 -> 83557.941 | D17: =D15+D16 -> 90184.341 | E17: =E15+E16 -> 95551.725
B19: TOTAL STOCKHOLDERS' EQUITY ($mm) | C19: ='Historical Financials'!$C$45+'Income Statement'!C29+'SBC & Dilution Schedule'!C10 -> 3986.9221 | D19: =C19+'Income Statement'!D29+'SBC & Dilution Schedule'!D10 -> 4358.2273 | E19: =D19+'Income Statement'!E29+'SBC & Dilution Schedule'!E10 -> 4598.1072
B21: BALANCE CHECK (Assets - Liabilities - Equity, should = 0) | C21: =C12-C17-C19 -> 0 | D21: =D12-D17-D19 -> 0 | E21: =E12-E17-E19 -> 0
B23: BASE CASE
C24: FY2026E | D24: FY2027E | E24: FY2028E
B25: Cash & equivalents, corporate ($mm) | C25: ='Cash Flow Statement'!C32 -> 2451.3036 | D25: ='Cash Flow Statement'!D32 -> 3251.2383 | E25: ='Cash Flow Statement'!E32 -> 4106.338
B26: Other corporate assets, net ($mm, PP&E + other — reconciling combination) | C26: ='Historical Financials'!$C$36+'Cash Flow Statement'!C27-'Income Statement'!C52 -> 2407.9994 | D26: =C26+'Cash Flow Statement'!D27-'Income Statement'!D52 -> 2287.2397 | E26: =D26+'Cash Flow Statement'!E27-'Income Statement'!E52 -> 2152.8576
B27: Total corporate assets ($mm) | C27: =C25+C26 -> 4859.3031 | D27: =D25+D26 -> 5538.4781 | E27: =E25+E26 -> 6259.1956
B28: USDC reserve assets (pass-through, $mm) | C28: ='Income Statement'!C37*1000 -> 90360 | D28: ='Income Statement'!D37*1000 -> 106624.8 | E28: ='Income Statement'!E37*1000 -> 123684.77
B29: TOTAL ASSETS ($mm) | C29: =C27+C28 -> 95219.303 | D29: =D27+D28 -> 112163.28 | E29: =E27+E28 -> 129943.96
B31: Other corporate liabilities ($mm, accrued exp., deferred rev., etc.) | C31: ='Historical Financials'!$C$40 -> 727.941 | D31: ='Historical Financials'!$C$40 -> 727.941 | E31: ='Historical Financials'!$C$40 -> 727.941 | F31: Held flat at the Q2'26A anchor — a fuller build would itemize and grow this with revenue/headcount
B32: Total corporate liabilities ($mm, no debt outstanding) | C32: =C31 -> 727.941 | D32: =D31 -> 727.941 | E32: =E31 -> 727.941
B33: USDC in circulation / stablecoin deposits (pass-through, $mm) | C33: =C28 -> 90360 | D33: =D28 -> 106624.8 | E33: =E28 -> 123684.77
B34: TOTAL LIABILITIES ($mm) | C34: =C32+C33 -> 91087.941 | D34: =D32+D33 -> 107352.74 | E34: =E32+E33 -> 124412.71
B36: TOTAL STOCKHOLDERS' EQUITY ($mm) | C36: ='Historical Financials'!$C$45+'Income Statement'!C58+'SBC & Dilution Schedule'!C20 -> 4131.3621 | D36: =C36+'Income Statement'!D58+'SBC & Dilution Schedule'!D20 -> 4810.5371 | E36: =D36+'Income Statement'!E58+'SBC & Dilution Schedule'!E20 -> 5531.2546
B38: BALANCE CHECK (Assets - Liabilities - Equity, should = 0) | C38: =C29-C34-C36 -> 0 | D38: =D29-D34-D36 -> 0 | E38: =E29-E34-E36 -> 0
B40: BULL CASE
C41: FY2026E | D41: FY2027E | E41: FY2028E
B42: Cash & equivalents, corporate ($mm) | C42: ='Cash Flow Statement'!C47 -> 2613.752 | D42: ='Cash Flow Statement'!D47 -> 3878.9798 | E42: ='Cash Flow Statement'!E47 -> 5559.294
B43: Other corporate assets, net ($mm, PP&E + other — reconciling combination) | C43: ='Historical Financials'!$C$36+'Cash Flow Statement'!C42-'Income Statement'!C81 -> 2402.6343 | D43: =C43+'Cash Flow Statement'!D42-'Income Statement'!D81 -> 2251.1249 | E43: =D43+'Cash Flow Statement'!E42-'Income Statement'!E81 -> 2043.5739
B44: Total corporate assets ($mm) | C44: =C42+C43 -> 5016.3863 | D44: =D42+D43 -> 6130.1047 | E44: =E42+E43 -> 7602.8679
B45: USDC reserve assets (pass-through, $mm) | C45: ='Income Statement'!C66*1000 -> 101655 | D45: ='Income Statement'!D66*1000 -> 134184.6 | E45: ='Income Statement'!E66*1000 -> 174439.98
B46: TOTAL ASSETS ($mm) | C46: =C44+C45 -> 106671.39 | D46: =D44+D45 -> 140314.7 | E46: =E44+E45 -> 182042.85
B48: Other corporate liabilities ($mm, accrued exp., deferred rev., etc.) | C48: ='Historical Financials'!$C$40 -> 727.941 | D48: ='Historical Financials'!$C$40 -> 727.941 | E48: ='Historical Financials'!$C$40 -> 727.941 | F48: Held flat at the Q2'26A anchor — a fuller build would itemize and grow this with revenue/headcount
B49: Total corporate liabilities ($mm, no debt outstanding) | C49: =C48 -> 727.941 | D49: =D48 -> 727.941 | E49: =E48 -> 727.941
B50: USDC in circulation / stablecoin deposits (pass-through, $mm) | C50: =C45 -> 101655 | D50: =D45 -> 134184.6 | E50: =E45 -> 174439.98
B51: TOTAL LIABILITIES ($mm) | C51: =C49+C50 -> 102382.94 | D51: =D49+D50 -> 134912.54 | E51: =E49+E50 -> 175167.92
B53: TOTAL STOCKHOLDERS' EQUITY ($mm) | C53: ='Historical Financials'!$C$45+'Income Statement'!C87+'SBC & Dilution Schedule'!C30 -> 4288.4453 | D53: =C53+'Income Statement'!D87+'SBC & Dilution Schedule'!D30 -> 5402.1637 | E53: =D53+'Income Statement'!E87+'SBC & Dilution Schedule'!E30 -> 6874.9269
...

Sheet Cash Flow Statement
A2: CASH FLOW STATEMENT — FY2026E-FY2028E, BY SCENARIO
B3: v3: a real cash flow statement, replacing the EBITDA-based 'FCF proxy.' Unlevered FCF (used in the Valuation tab's DCF) = Cash flow from operations - Capex; with no debt outstanding, unlevered and levered FCF are the same here, so no further adjustment is needed. Financing activities are assumed at $0 (no debt issuance, buybacks, or cash-financed equity activity) — a simplification, not a disclosed fact.
B6: BEAR CASE
C7: FY2026E | D7: FY2027E | E7: FY2028E
B8: Net income ($mm) | C8: ='Income Statement'!C29 -> 227.96974 | D8: ='Income Statement'!D29 -> 129.04223 | E8: ='Income Statement'!E29 -> 11.187182
B9: + Depreciation & amortization ($mm) | C9: ='Income Statement'!C23 -> 117.1658 | D9: ='Income Statement'!D23 -> 119.70642 | E9: ='Income Statement'!E23 -> 115.6916
B10: + Stock-based compensation ($mm) | C10: ='SBC & Dilution Schedule'!C10 -> 248.97733 | D10: ='SBC & Dilution Schedule'!D10 -> 242.26299 | E10: ='SBC & Dilution Schedule'!E10 -> 228.6927
B11: CASH FLOW FROM OPERATIONS ($mm) | C11: =C8+C9+C10 -> 594.11286 | D11: =D8+D9+D10 -> 491.01164 | E11: =E8+E9+E10 -> 355.57148
B12: Capex ($mm) | C12: ='Income Statement'!C15*Assumptions!$C$66 -> 23.43316 | D12: ='Income Statement'!D15*Assumptions!$D$66 -> 22.801222 | E12: ='Income Statement'!E15*Assumptions!$E$66 -> 21.524018
B13: CASH FLOW FROM INVESTING ($mm, = -Capex) | C13: =-C12 -> -23.43316 | D13: =-D12 -> -22.801222 | E13: =-E12 -> -21.524018
B14: CASH FLOW FROM FINANCING ($mm) | C14: 0 | D14: 0 | E14: 0 | F14: No debt issuance, buybacks, or cash-financed equity activity assumed
B15: NET CHANGE IN CASH ($mm) | C15: =C11+C13+C14 -> 570.6797 | D15: =D11+D13+D14 -> 468.21041 | E15: =E11+E13+E14 -> 334.04746
B16: Beginning cash ($mm) | C16: ='Historical Financials'!$C$35 -> 1730.126 | D16: =C17 -> 2300.8057 | E16: =D17 -> 2769.0161
B17: Ending cash ($mm) | C17: =C16+C15 -> 2300.8057 | D17: =D16+D15 -> 2769.0161 | E17: =E16+E15 -> 3103.0636
B19: UNLEVERED FREE CASH FLOW ($mm, = CFO - Capex) | C19: =C11-C12 -> 570.6797 | D19: =D11-D12 -> 468.21041 | E19: =E11-E12 -> 334.04746
B21: BASE CASE
C22: FY2026E | D22: FY2027E | E22: FY2028E
B23: Net income ($mm) | C23: ='Income Statement'!C58 -> 379.95833 | D23: ='Income Statement'!D58 -> 430.552 | E23: ='Income Statement'!E58 -> 471.15076
B24: + Depreciation & amortization ($mm) | C24: ='Income Statement'!C52 -> 128.762 | D24: ='Income Statement'!D52 -> 152.72554 | E24: ='Income Statement'!E52 -> 172.77699
B25: + Stock-based compensation ($mm) | C25: ='SBC & Dilution Schedule'!C20 -> 241.42875 | D25: ='SBC & Dilution Schedule'!D20 -> 248.62298 | E25: ='SBC & Dilution Schedule'!E20 -> 249.56677
B26: CASH FLOW FROM OPERATIONS ($mm) | C26: =C23+C24+C25 -> 750.14908 | D26: =D23+D24+D25 -> 831.90052 | E26: =E23+E24+E25 -> 893.49452
B27: Capex ($mm) | C27: ='Income Statement'!C44*Assumptions!$C$67 -> 28.97145 | D27: ='Income Statement'!D44*Assumptions!$D$67 -> 31.965811 | E27: ='Income Statement'!E44*Assumptions!$E$67 -> 38.394887
B28: CASH FLOW FROM INVESTING ($mm, = -Capex) | C28: =-C27 -> -28.97145 | D28: =-D27 -> -31.965811 | E28: =-E27 -> -38.394887
B29: CASH FLOW FROM FINANCING ($mm) | C29: 0 | D29: 0 | E29: 0 | F29: No debt issuance, buybacks, or cash-financed equity activity assumed
B30: NET CHANGE IN CASH ($mm) | C30: =C26+C28+C29 -> 721.17763 | D30: =D26+D28+D29 -> 799.93471 | E30: =E26+E28+E29 -> 855.09963
B31: Beginning cash ($mm) | C31: ='Historical Financials'!$C$35 -> 1730.126 | D31: =C32 -> 2451.3036 | E31: =D32 -> 3251.2383
B32: Ending cash ($mm) | C32: =C31+C30 -> 2451.3036 | D32: =D31+D30 -> 3251.2383 | E32: =E31+E30 -> 4106.338
B34: UNLEVERED FREE CASH FLOW ($mm, = CFO - Capex) | C34: =C26-C27 -> 721.17763 | D34: =D26-D27 -> 799.93471 | E34: =E26-E27 -> 855.09963
B36: BULL CASE
C37: FY2026E | D37: FY2027E | E37: FY2028E
B38: Net income ($mm) | C38: ='Income Statement'!C87 -> 533.10702 | D38: ='Income Statement'!D87 -> 838.24685 | E38: ='Income Statement'!E87 -> 1184.4979
B39: + Depreciation & amortization ($mm) | C39: ='Income Statement'!C81 -> 140.2076 | D39: ='Income Statement'!D81 -> 206.60369 | E39: ='Income Statement'!E81 -> 288.26528
B40: + Stock-based compensation ($mm) | C40: ='SBC & Dilution Schedule'!C30 -> 245.3633 | D40: ='SBC & Dilution Schedule'!D30 -> 275.47158 | E40: ='SBC & Dilution Schedule'!E30 -> 288.26528
B41: CASH FLOW FROM OPERATIONS ($mm) | C41: =C38+C39+C40 -> 918.67792 | D41: =D38+D39+D40 -> 1320.3221 | E41: =E38+E39+E40 -> 1761.0284
B42: Capex ($mm) | C42: ='Income Statement'!C73*Assumptions!$C$68 -> 35.0519 | D42: ='Income Statement'!D73*Assumptions!$D$68 -> 55.094316 | E42: ='Income Statement'!E73*Assumptions!$E$68 -> 80.714278
B43: CASH FLOW FROM INVESTING ($mm, = -Capex) | C43: =-C42 -> -35.0519 | D43: =-D42 -> -55.094316 | E43: =-E42 -> -80.714278
B44: CASH FLOW FROM FINANCING ($mm) | C44: 0 | D44: 0 | E44: 0 | F44: No debt issuance, buybacks, or cash-financed equity activity assumed
B45: NET CHANGE IN CASH ($mm) | C45: =C41+C43+C44 -> 883.62602 | D45: =D41+D43+D44 -> 1265.2278 | E45: =E41+E43+E44 -> 1680.3142
B46: Beginning cash ($mm) | C46: ='Historical Financials'!$C$35 -> 1730.126 | D46: =C47 -> 2613.752 | E46: =D47 -> 3878.9798
B47: Ending cash ($mm) | C47: =C46+C45 -> 2613.752 | D47: =D46+D45 -> 3878.9798 | E47: =E46+E45 -> 5559.294
...

Sheet SBC & Dilution Schedule
A2: SBC & DILUTION SCHEDULE — FY2026E-FY2028E, BY SCENARIO
B3: v3: connects SBC expense to the Income Statement (as a real P&L deduction from EBITDA to EBIT), the Cash Flow Statement (as a non-cash add-back), and the diluted share count used everywhere else in the model — instead of a standalone dilution %% detached from the dollar economics. Basic shares and the RSU/option overhang are grown using the SAME case-specific %% dilution rate (preserving a constant overhang-to-basic ratio) rather than a fully itemized grant/vest/forfeit waterfall, since Circle does not disclose enough proxy-level detail to build that waterfall with real numbers — a labeled simplification, not fabricated precision. No repurchases are assumed (none announced).
B6: BEAR CASE
C7: FY2026E | D7: FY2027E | E7: FY2028E
B8: Basic shares outstanding, beginning of year (mm) | C8: =Cover_Shares -> 253.88 | D8: =C12 -> 261.4964 | E8: =D12 -> 269.34129
B9: Diluted shares outstanding, beginning of year (mm) | C9: =Cover_DilShares -> 268.6 | D9: =C11 -> 276.658 | E9: =D11 -> 284.95774
B10: SBC expense ($mm, = Total Revenue x SBC%) | C10: ='Income Statement'!C15*Assumptions!$C$52 -> 248.97733 | D10: ='Income Statement'!D15*Assumptions!$D$52 -> 242.26299 | E10: ='Income Statement'!E15*Assumptions!$E$52 -> 228.6927
B11: Diluted shares outstanding, end of year (mm) | C11: =C9*(1+Assumptions!$C$47) -> 276.658 | D11: =D9*(1+Assumptions!$D$47) -> 284.95774 | E11: =E9*(1+Assumptions!$E$47) -> 293.50647
B12: Basic shares outstanding, end of year (mm) | C12: =C8*(1+Assumptions!$C$47) -> 261.4964 | D12: =D8*(1+Assumptions!$D$47) -> 269.34129 | E12: =E8*(1+Assumptions!$E$47) -> 277.42153
B13: Implied RSU/option overhang, end of year (mm) | C13: =C11-C12 -> 15.1616 | D13: =D11-D12 -> 15.616448 | E13: =E11-E12 -> 16.084941
B14: Share repurchases (mm) | C14: 0 | D14: 0 | E14: 0 | F14: None announced/assumed
B16: BASE CASE
C17: FY2026E | D17: FY2027E | E17: FY2028E
B18: Basic shares outstanding, beginning of year (mm) | C18: =Cover_Shares -> 253.88 | D18: =C22 -> 258.9576 | E18: =D22 -> 264.13675
B19: Diluted shares outstanding, beginning of year (mm) | C19: =Cover_DilShares -> 268.6 | D19: =C21 -> 273.972 | E19: =D21 -> 279.45144
B20: SBC expense ($mm, = Total Revenue x SBC%) | C20: ='Income Statement'!C44*Assumptions!$C$53 -> 241.42875 | D20: ='Income Statement'!D44*Assumptions!$D$53 -> 248.62298 | E20: ='Income Statement'!E44*Assumptions!$E$53 -> 249.56677
B21: Diluted shares outstanding, end of year (mm) | C21: =C19*(1+Assumptions!$C$48) -> 273.972 | D21: =D19*(1+Assumptions!$D$48) -> 279.45144 | E21: =E19*(1+Assumptions!$E$48) -> 285.04047
B22: Basic shares outstanding, end of year (mm) | C22: =C18*(1+Assumptions!$C$48) -> 258.9576 | D22: =D18*(1+Assumptions!$D$48) -> 264.13675 | E22: =E18*(1+Assumptions!$E$48) -> 269.41949
B23: Implied RSU/option overhang, end of year (mm) | C23: =C21-C22 -> 15.0144 | D23: =D21-D22 -> 15.314688 | E23: =E21-E22 -> 15.620982
B24: Share repurchases (mm) | C24: 0 | D24: 0 | E24: 0 | F24: None announced/assumed
B26: BULL CASE
C27: FY2026E | D27: FY2027E | E27: FY2028E
B28: Basic shares outstanding, beginning of year (mm) | C28: =Cover_Shares -> 253.88 | D28: =C32 -> 256.4188 | E28: =D32 -> 258.98299
B29: Diluted shares outstanding, beginning of year (mm) | C29: =Cover_DilShares -> 268.6 | D29: =C31 -> 271.286 | E29: =D31 -> 273.99886
B30: SBC expense ($mm, = Total Revenue x SBC%) | C30: ='Income Statement'!C73*Assumptions!$C$54 -> 245.3633 | D30: ='Income Statement'!D73*Assumptions!$D$54 -> 275.47158 | E30: ='Income Statement'!E73*Assumptions!$E$54 -> 288.26528
B31: Diluted shares outstanding, end of year (mm) | C31: =C29*(1+Assumptions!$C$49) -> 271.286 | D31: =D29*(1+Assumptions!$D$49) -> 273.99886 | E31: =E29*(1+Assumptions!$E$49) -> 276.73885
B32: Basic shares outstanding, end of year (mm) | C32: =C28*(1+Assumptions!$C$49) -> 256.4188 | D32: =D28*(1+Assumptions!$D$49) -> 258.98299 | E32: =E28*(1+Assumptions!$E$49) -> 261.57282
B33: Implied RSU/option overhang, end of year (mm) | C33: =C31-C32 -> 14.8672 | D33: =D31-D32 -> 15.015872 | E33: =E31-E32 -> 15.166031
B34: Share repurchases (mm) | C34: 0 | D34: 0 | E34: 0 | F34: None announced/assumed

Sheet Valuation
A2: COMPARABLE COMPANY MULTIPLES
B4: Company | C4: Price | D4: Mkt Cap ($bn) | E4: EV ($bn) | F4: TTM Rev ($bn) | G4: EV/Rev (TTM) | H4: Fwd P/E
B5: Circle Internet Group (CRCL) | C5: =Cover_Price -> 87.98 | D5: =Cover_MktCap/1000 -> 22.336362 | E5: =Cover_MktCap/1000-Cover_NetCash/1000 -> 20.606362 | F5: 2.7 | G5: =E5/F5 -> 7.6319861 | H5: 54.6
B6: Coinbase Global (COIN) | C6: 148 | D6: 39.1 | E6: 37 | F6: 6.04 | G6: =E6/F6 -> 6.1258278 | H6: 129
B7: PayPal Holdings (PYPL) | C7: 61 | D7: 52.5 | E7: 55 | F7: 34.13 | G7: =E7/F7 -> 1.6114855 | H7: 11
B8: Visa Inc. (V) — reference only | C8: 365 | D8: 676 | E8: n/a | F8: 44.49 | G8: n/a | H8: 24.8
B9: Mastercard (MA) — reference only | C9: 569 | D9: 499 | E9: n/a | F9: 35.08 | G9: n/a | H9: 26.4
B11: Note: EV/Revenue is not a standard metric for float/custody-income bank holding companies — omitted from this grid. Visa/Mastercard shown for reference only (network/toll-booth economics, not a reserve-income model — not true comps for a multiple to apply to CRCL). EV/EBITDA is not shown for comps because TTM Adj. EBITDA by comp was not sourced this pass; the exit-multiple assumptions on the Assumptions tab are calibrated qualitatively against typical growth-fintech EV/EBITDA ranges instead — a gap worth closing in a future pass.
A13: SELL-SIDE COVERAGE SNAPSHOT (Jul-Aug 2026)
B14: Date (2026) | C14: Firm | D14: Rating | E14: Price Target | F14: Upside/(Downside) | G14: Notes
B15: Aug 12 | C15: TD Cowen | D15: Buy | E15: 87 | F15: =E15/Cover_Price-1 -> -0.011138895
B16: Aug 6 | C16: Canaccord Genuity | D16: Buy | E16: 130 | F16: =E16/Cover_Price-1 -> 0.47760855
B17: Aug 6 | C17: Morgan Stanley | D17: Underweight | E17: 37 | F17: =E17/Cover_Price-1 -> -0.57944987
B18: Aug 6 | C18: HC Wainwright | D18: Buy | E18: 104 | F18: =E18/Cover_Price-1 -> 0.18208684
B19: Aug 6 | C19: Needham | D19: Buy | E19: 127 | F19: =E19/Cover_Price-1 -> 0.44350989
B20: Jul 31 | C20: Mizuho | D20: Neutral | E20: 45 | F20: =E20/Cover_Price-1 -> -0.48852012
B21: Jul 22 | C21: Raymond James | D21: Market Perform | E21: n/a | F21: -
B22: Jul 14 | C22: Mizuho | D22: Underperform | E22: 50 | F22: =E22/Cover_Price-1 -> -0.43168902
B23: Jul 13 | C23: Baird | D23: Outperform | E23: 100 | F23: =E23/Cover_Price-1 -> 0.13662196
B24: Jul 2 | C24: Goldman Sachs | D24: Neutral | E24: 96 | F24: =E24/Cover_Price-1 -> 0.091157081
B25: Jul 1 | C25: Compass Point | D25: Neutral | E25: 55 | F25: =E25/Cover_Price-1 -> -0.37485792
B26: Jul 1 | C26: Susquehanna | D26: Neutral | E26: 69 | F26: =E26/Cover_Price-1 -> -0.21573085
B27: Consensus (approx.) | C27: ~23-27 analysts: ~11 Buy, 2 Outperform, 12 Hold, 1 Sell | E27: 105 | F27: =E27/Cover_Price-1 -> 0.19345306
B28: Read-through: extreme dispersion (Morgan Stanley $37 vs. Canaccord $130 — a >3x spread) reflects genuine analyst disagreement about how much further reserve-yield compression is coming and whether USDC circulation growth/diversification can offset it — the same tension this model's Bear/Base/Bull spread is built to make explicit and quantified rather than just described.
A31: SCENARIO VALUATION — METHOD 1: EXIT EV/ADJ. EBITDA MULTIPLE (FY2028E)
C32: Bear | D32: Base | E32: Bull
B33: FY2028E Adj. EBITDA ($mm) | C33: ='Income Statement'!$E$21 -> 297.99087 | D33: ='Income Statement'!$E$50 -> 958.18271 | E33: ='Income Statement'!$E$79 -> 2015.3406
B34: Exit EV/Adj. EBITDA multiple | C34: =Assumptions!$C$77 -> 7.5 | D34: =Assumptions!$D$77 -> 9.5 | E34: =Assumptions!$E$77 -> 14
B35: Implied enterprise value ($mm) | C35: =C33*C34 -> 2234.9316 | D35: =D33*D34 -> 9102.7358 | E35: =E33*E34 -> 28214.768
B36: Implied equity value ($mm, + net cash) | C36: =C35+Cover_NetCash -> 3964.9316 | D36: =D35+Cover_NetCash -> 10832.736 | E36: =E35+Cover_NetCash -> 29944.768
B37: FY2028E diluted shares (mm) | C37: ='Income Statement'!$E$31 -> 293.50647 | D37: ='Income Statement'!$E$60 -> 285.04047 | E37: ='Income Statement'!$E$89 -> 276.73885
B38: Implied share price (Method 1) | C38: =IFERROR(C36/C37,"-") -> 13.508839 | D38: =IFERROR(D36/D37,"-") -> 38.004203 | E38: =IFERROR(E36/E37,"-") -> 108.20587
A40: SCENARIO VALUATION — METHOD 2: 3-YEAR DCF ON REAL UNLEVERED FCF (FY2026E-FY2028E)
B41: v3: FCF here is real unlevered free cash flow from the Cash Flow Statement tab (Net income + D&A + SBC - Capex, i.e. CFO - Capex), not the v2.1 EBITDA-based proxy — it reflects actual taxes paid (via net income), D&A, SBC add-back, and capex, not an illustrative flat-rate approximation.
C43: Bear | D43: Base | E43: Bull
B44: PV of FY26E-FY28E unlevered FCF, discounted at WACC ($mm) | C44: ='Cash Flow Statement'!$C$19/(1+Assumptions!$C$75)^1+'Cash Flow Statement'!$D$19/(1+Assumptions!$C$75)^2+'Cash Flow Statement'!$E$19/(1+Assumptions!$C$75)^3 -> 1120.5583 | D44: ='Cash Flow Statement'!$C$34/(1+Assumptions!$C$75)^1+'Cash Flow Statement'!$D$34/(1+Assumptions!$C$75)^2+'Cash Flow Statement'!$E$34/(1+Assumptions!$C$75)^3 -> 1890.2547 | E44: ='Cash Flow Statement'!$C$49/(1+Assumptions!$C$75)^1+'Cash Flow Statement'!$D$49/(1+Assumptions!$C$75)^2+'Cash Flow Statement'!$E$49/(1+Assumptions!$C$75)^3 -> 2993.5981
B45: PV of terminal value (Gordon growth on FY28E unlevered FCF) | C45: =('Cash Flow Statement'!$E$19*(1+Assumptions!$C$76)/(Assumptions!$C$75-Assumptions!$C$76))/(1+Assumptions!$C$75)^3 -> 2721.127 | D45: =('Cash Flow Statement'!$E$34*(1+Assumptions!$C$76)/(Assumptions!$C$75-Assumptions!$C$76))/(1+Assumptions!$C$75)^3 -> 6965.5813 | E45: =('Cash Flow Statement'!$E$49*(1+Assumptions!$C$76)/(Assumptions!$C$75-Assumptions!$C$76))/(1+Assumptions!$C$75)^3 -> 13687.721
B46: Enterprise value ($mm) | C46: =C44+C45 -> 3841.6853 | D46: =D44+D45 -> 8855.836 | E46: =E44+E45 -> 16681.319
B47: Terminal value as % of EV | C47: =IFERROR(C45/C46,"-") -> 0.70831596 | D47: =IFERROR(D45/D46,"-") -> 0.78655266 | E47: =IFERROR(E45/E46,"-") -> 0.82054188
B48: Implied equity value ($mm, + net cash) | C48: =C46+Cover_NetCash -> 5571.6853 | D48: =D46+Cover_NetCash -> 10585.836 | E48: =E46+Cover_NetCash -> 18411.319
...

Sheet Competitive & Distrib Risks
A2: USDC MARKET SHARE — TREND AND CONTEXT
B4: Metric | C4: Value | D4: Source / note
B5: USDC market cap ($bn) | C5: 71.93 | D5: Fool.com, ~Aug 10 2026
B6: USDC share of total stablecoin market | C6: 0.23 | D6: Fool.com / TradingView cross-check, ~Aug 2026
B7: USDC peak share (approx., prior period) | C7: 0.3488 | D7: TradingView chart annotation — exact date not confirmed
B8: USDT (Tether) market cap ($bn) | C8: 183.4 | D8: Fool.com, ~Aug 10 2026
B9: USDT share of total stablecoin market | C9: 0.59 | D9: Fool.com, ~Aug 10 2026
B10: Total stablecoin market ($bn, implied) | C10: 310.5 | D10: Implied from USDT $ and % share
B12: USDC's share of the stablecoin market has fallen materially from a prior peak (~35%) to roughly 23% as of Aug 2026 — Circle is not the dominant player in its own product category, USDT is. This is a longer-running, structural trend distinct from the more recent Open USD threat discussed below; no single historical data series with confirmed dates was found this pass to chart the full trajectory (flagged in Sources & Notes) — treat the peak figure as directional, not precise.
A14: COINBASE DISTRIBUTION SENSITIVITY
B15: Coinbase is Circle's largest single distribution partner; the distribution-cost ratio (currently ~61.5% of reserve income, per Historical Financials) is the single biggest lever in the entire model besides the Fed rate path itself. This table shows the Adj. EBITDA impact if that ratio moves — e.g. from a renegotiated Coinbase deal, or competitive pressure from Open USD forcing Circle to share more.
B17: Distribution ratio scenario | C17: Reserve income ($mm, FY26E Base) | D17: RLDC ($mm) | E17: Adj. EBITDA impact vs. current ($mm)
B18: Current (~61.5%) | C18: ='Income Statement'!$C$40 -> 2899.05 | D18: =C18*(1-('Historical Financials'!$G$12+0)) -> 1117.1568 | E18: 0
B19: +5pt (renegotiation risk) | C19: ='Income Statement'!$C$40 -> 2899.05 | D19: =C19*(1-('Historical Financials'!$G$12+0.05)) -> 972.20425 | E19: =D19-D18 -> -144.9525
B20: +10pt (Open USD pressure) | C20: ='Income Statement'!$C$40 -> 2899.05 | D20: =C20*(1-('Historical Financials'!$G$12+0.1)) -> 827.25175 | E20: =D20-D18 -> -289.905
B21: +15pt (severe — OUSD-style yield-sharing) | C21: ='Income Statement'!$C$40 -> 2899.05 | D21: =C21*(1-('Historical Financials'!$G$12+0.15)) -> 682.29925 | E21: =D21-D18 -> -434.8575
B22: -5pt (Circle holds/improves terms) | C22: ='Income Statement'!$C$40 -> 2899.05 | D22: =C22*(1-('Historical Financials'!$G$12+-0.05)) -> 1262.1093 | E22: =D22-D18 -> 144.9525
A25: USDC MARKET-SHARE-LOSS SCENARIO (ILLUSTRATIVE)
B26: No analyst or company estimate for Open USD's potential market-share impact on USDC was found in this pass — CoinShares (Jul 13 2026) called it 'the most credible threat since inception' but gave no number, and Coindesk (Aug 3 2026) reported Visa/Mastercard/Coinbase publicly still support USDC too, i.e. no confirmed volume shift yet. The scenarios below are this model's own illustrative construction to make the risk quantifiable rather than leaving it narrative-only — label them as such, not as a forecast.
B28: Circulation lost to competitors by FY28E | C28: FY28E circulation impact ($bn) | D28: FY28E reserve income impact ($mm, Base yield)
B29: 0% | C29: =-'Income Statement'!$E$37*0 -> 0 | D29: =C29*1000*'Income Statement'!$E$39 -> 0
B30: 5% | C30: =-'Income Statement'!$E$37*0.05 -> -6.1842384 | D30: =C30*1000*'Income Statement'!$E$39 -> -179.34291
B31: 10% | C31: =-'Income Statement'!$E$37*0.1 -> -12.368477 | D31: =C31*1000*'Income Statement'!$E$39 -> -358.68583
