Workbook

Sheet Cover
B2: THE GOLDMAN SACHS GROUP, INC.
B3: GS — Equity Research Model — Fundamental + Technical
B4: Prepared for informational/educational purposes — not investment advice
B5: Model date: | C5: 2026-08-30
A7: MARKET SNAPSHOT
B8: Last price ($) | C8: 1033.99 | F8: stockanalysis.com close 28-Aug-2026
B9: 52-week high ($) | C9: 1125 | F9: heygotrade quote page; intraday high 14-Jul-2026 post-2Q26 print
B10: 52-week low ($) | C10: 691.3 | F10: heygotrade quote page — see Sources for conflicting 52wk figures
B11: Basic shares outstanding (mm) | C11: 298.4 | F11: 2Q26 earnings presentation, p.11
B12: Free float (mm) | C12: 289.53 | F12: StockTitan GS stock data
B13: Market capitalisation ($mm) | C13: =Cover_Price*Cover_Shares -> 308542.62 | F13: Formula: price x basic shares. Sources quote $301bn-$315bn
B14: Book value per share ($) | C14: 367.67 | F14: 2Q26 earnings presentation
B15: Tangible book value per share ($) | C15: 336.61 | F15: 2Q26 earnings presentation (non-GAAP)
B16: Price / tangible book (x) | C16: =Cover_Price/C15 -> 3.0717745 | F16: Formula: price / TBVPS
B17: TTM diluted EPS ($) | C17: 64.63 | F17: stockanalysis.com TTM to Jun-2026
B18: Trailing P/E (x) | C18: =Cover_Price/C17 -> 15.998607 | F18: Formula: price / TTM EPS
B19: Forward P/E (x) | C19: 14.82 | F19: stockanalysis.com, 29-Aug-2026
B20: Indicated annual dividend ($) | C20: 20 | F20: $5.00/qtr declared for 3Q26 x 4
B21: Dividend yield (%) | C21: =C20/Cover_Price -> 0.019342547 | F21: Formula: indicated DPS / price
A23: VALUATION DASHBOARD (live links to the Valuation tab)
B24: Bear-case blended target ($) | C24: =Valuation!C35 -> 508.33537
B25: Base-case blended target ($) | C25: =Valuation!D35 -> 812.79324
B26: Bull-case blended target ($) | C26: =Valuation!E35 -> 1281.2359
B27: Probability-weighted target ($, 25/50/25) | C27: =Valuation!D39 -> 853.78943
B28: Upside / (downside) to weighted target | C28: =Valuation!D40 -> -0.17427689
B29: Sell-side consensus target ($) | C29: ='Analyst Ratings'!C13 -> 1141.65
B30: Market-implied sustainable ROTE | C30: ='ROTE Driver Model'!D27 -> 0.23966534
A32: WHAT THE MARKET IS PRICING IN
B33: GS trades at roughly 3.1x tangible book on a 2Q26 annualised ROTE of 25.5%. Reverse-engineering the Gordon relationship P/TBV = (ROTE - g) / (COE - g) at a 10.5% cost of equity and 4.0% long-run tangible book growth, the current price embeds a SUSTAINABLE ROTE of roughly 24% - against a firm-set through-the-cycle target of 15-17% ROTE and an FY2025 actual of 16.0%. The current price therefore sits closer to this model's Bull case than its Base case. For today's price to be justified on this framework, one of three things must be true: (i) the 2026 capital-markets and AI-financing cycle is a new plateau rather than a peak, so mid-20s ROTE is the new normal; (ii) the 2026 capital deregulation package permanently lowers the equity base GS must hold against the same earnings; or (iii) GS's cost of equity has fallen toward 9%, i.e. the market now views the earnings stream as materially less cyclical than history implies. Note the tension flagged on the Valuation tab: on a PEER-RELATIVE basis versus MS and JPM at spot returns, GS screens cheap, not expensive. The two methods only reconcile once ROTE is normalised. That disagreement is the investment question; this model does not resolve it.
A35: REPORT CONTENTS
B36: 1. Quarterly Financials — 8 quarters of net revenues, segments, returns and book value
B37: 2. ROTE Driver Model — the single biggest valuation lever: sustainable ROTE -> justified P/TBV
B38: 3. Valuation — peer multiples, two valuation methods, bear/base/bull scenarios
B39: 4. Analyst Ratings — sell-side coverage and the spread of targets
B40: 5. Technical & Market — price levels, moving averages, positioning
B41: 6. Catalyst Calendar — historical reactions and forward catalysts
B42: 7. Sources & Notes — citations and data-quality flags
B44: Color key:
B45: Blue = hardcoded input / assumption
B46: Black = formula
...

Sheet Quarterly Financials
A2: GS — QUARTERLY FINANCIALS ($mm unless noted)
B3: Source: GS quarterly earnings releases / 8-K exhibits (3Q24 through 2Q26) and the 2Q26 earnings results presentation. Rows marked 'derived' in column K are NOT directly disclosed — they are computed from disclosed YoY/QoQ change figures and are flagged as such on the Sources tab.
B5: Line item | C5: 3Q24 | D5: 4Q24 | E5: 1Q25 | F5: 2Q25 | G5: 3Q25 | H5: 4Q25 | I5: 1Q26 | J5: 2Q26
B6: Global Banking & Markets | F6: 10133 | H6: 10410 | I6: 12738 | J6: 15520 | K6: 2Q25/1Q26/2Q26 from 2Q26 pres.; 4Q25 from Zacks recap
B7: Asset & Wealth Management | F7: 3831 | H7: 4720 | I7: 4078 | J7: 4597 | K7: Same sources as GBM row
B8: Platform Solutions | F8: 619 | I8: 411 | J8: 221 | K8: 4Q25 depressed by Apple Card held-for-sale markdowns
B9: Net revenues (total) | C9: 12700 | D9: 13870 | E9: 15060 | F9: 14583 | G9: 15180 | H9: 13450 | I9: 17227 | J9: 20338 | K9: All eight from GS earnings releases
B10: Provision for credit losses | F10: 378 | H10: -2120 | I10: 315 | J10: 102 | K10: 2Q25 derived from '2Q26 -73% YoY'; 4Q25 = net benefit incl. $2.48bn Apple Card release
B11: Operating expenses | F11: 9264 | I11: 10426 | J11: 11673 | K11: 2Q25/1Q26 derived from 2Q26 pres. change figures
B12: Pre-tax earnings | F12: 4950 | I12: 6486 | J12: 8563 | K12: 2Q25/1Q26 derived from 2Q26 pres. change figures
B13: Net earnings | C13: 2990 | D13: 4110 | E13: 4740 | F13: 3720 | G13: 4100 | H13: 4620 | I13: 5630 | J13: 6628
B14: Net earnings to common | F14: 3477 | I14: 5403 | J14: 6399 | K14: 2Q25/1Q26 derived from 2Q26 pres. change figures
B16: Diluted EPS ($) | C16: 8.4 | D16: 11.95 | E16: 14.12 | F16: 10.91 | G16: 12.25 | H16: 14.01 | I16: 17.55 | J16: 20.98
B17: Book value per share ($) | D17: 336.77 | F17: 349.74 | G17: 353.79 | H17: 357.6 | I17: 361.19 | J17: 367.67
B18: Tangible book value per share ($) | H18: 335.49 | I18: 336.28 | J18: 336.61 | K18: Disclosed from 4Q25; earlier quarters not captured in sourcing
B19: Basic shares (mm) | H19: 307.1 | I19: 302 | J19: 298.4
B20: Diluted shares (mm) | J20: 305 | K20: 2Q26 derived: net earnings to common / diluted EPS
B22: ROE (annualised) | C22: 0.104 | D22: 0.146 | E22: 0.169 | F22: 0.128 | G22: 0.142 | H22: 0.16 | I22: 0.198 | J22: 0.235 | K22: 1Q25 derived from 1H25 YTD ROE of 14.8% and 2Q25 of 12.8%
B23: ROTE (annualised) | D23: 0.155 | F23: 0.136 | G23: 0.152 | H23: 0.171 | I23: 0.213 | J23: 0.255 | K23: 2Q25 derived: 2Q26 ROTE less the disclosed +11.9pp YoY change
B24: Efficiency ratio | F24: 0.634 | I24: 0.605 | J24: 0.574 | K24: 2Q25/1Q26 derived from 2Q26 pres. change figures
B25: CET1 ratio (Standardized) | H25: 0.143 | I25: 0.125 | J25: 0.129
B26: Supplementary leverage ratio | H26: 0.052 | I26: 0.047 | J26: 0.043
B28: Assets under supervision ($bn) | F28: 3293 | H28: 3606 | I28: 3650 | J28: 4041
B29: Loans ($bn) | F29: 217 | I29: 253 | J29: 261
B30: Net interest income | F30: 3110 | I30: 3700 | J30: 3950 | K30: 2Q25 derived from '2Q26 NII +27% YoY'; 1Q26 from 1Q26 call
B32: Net revenues YoY growth | C32: =IF(ISBLANK(C9),"n/a",IFERROR(C9/C9-1,"-")) -> 0 | D32: =IF(ISBLANK(D9),"n/a",IFERROR(D9/C9-1,"-")) -> 0.092125984 | E32: =IF(ISBLANK(E9),"n/a",IFERROR(E9/C9-1,"-")) -> 0.18582677 | F32: =IF(ISBLANK(F9),"n/a",IFERROR(F9/C9-1,"-")) -> 0.14826772 | G32: =IF(ISBLANK(G9),"n/a",IFERROR(G9/C9-1,"-")) -> 0.19527559 | H32: =IF(ISBLANK(H9),"n/a",IFERROR(H9/D9-1,"-")) -> -0.030281182 | I32: =IF(ISBLANK(I9),"n/a",IFERROR(I9/E9-1,"-")) -> 0.1438911 | J32: =IF(ISBLANK(J9),"n/a",IFERROR(J9/F9-1,"-")) -> 0.39463759 | K32: Blank for the first four quarters (no prior-year comparator in the table)
B33: Net margin (net earnings / net revenues) | C33: =IF(ISBLANK(C9),"n/a",IFERROR(C13/C9,"-")) -> 0.23543307 | D33: =IF(ISBLANK(D9),"n/a",IFERROR(D13/D9,"-")) -> 0.296323 | E33: =IF(ISBLANK(E9),"n/a",IFERROR(E13/E9,"-")) -> 0.31474104 | F33: =IF(ISBLANK(F9),"n/a",IFERROR(F13/F9,"-")) -> 0.25509154 | G33: =IF(ISBLANK(G9),"n/a",IFERROR(G13/G9,"-")) -> 0.27009223 | H33: =IF(ISBLANK(H9),"n/a",IFERROR(H13/H9,"-")) -> 0.34349442 | I33: =IF(ISBLANK(I9),"n/a",IFERROR(I13/I9,"-")) -> 0.32681256 | J33: =IF(ISBLANK(J9),"n/a",IFERROR(J13/J9,"-")) -> 0.32589242
B34: GBM share of net revenues | C34: =IF(ISBLANK(C6),"n/a",IFERROR(C6/C9,"-")) -> n/a | D34: =IF(ISBLANK(D6),"n/a",IFERROR(D6/D9,"-")) -> n/a | E34: =IF(ISBLANK(E6),"n/a",IFERROR(E6/E9,"-")) -> n/a | F34: =IF(ISBLANK(F6),"n/a",IFERROR(F6/F9,"-")) -> 0.69485017 | G34: =IF(ISBLANK(G6),"n/a",IFERROR(G6/G9,"-")) -> n/a | H34: =IF(ISBLANK(H6),"n/a",IFERROR(H6/H9,"-")) -> 0.7739777 | I34: =IF(ISBLANK(I6),"n/a",IFERROR(I6/I9,"-")) -> 0.73942068 | J34: =IF(ISBLANK(J6),"n/a",IFERROR(J6/J9,"-")) -> 0.76310355
B36: Read-through: the story is a violent, capital-markets-driven acceleration, not a steady compounding. Net revenues went from a $13-15bn quarterly band through 3Q25 to $17.2bn and then $20.3bn, and ROE roughly doubled from 12.8% in 2Q25 to 23.5% in 2Q26. Two-thirds of the incremental revenue came from Global Banking & Markets, whose share of the total rose from ~69% to ~76% - so the mix got MORE cyclical, not less, even as management emphasises the fee-based AWM franchise. Equities net revenues alone rose 72% YoY. Meanwhile the CET1 ratio fell from 14.3% to 12.9% and the SLR from 5.2% to 4.3% in two quarters: a meaningful part of the ROE step-up is a smaller equity denominator, not just a bigger numerator. 4Q25's revenue dip is an artefact of $2.26bn of Apple Card held-for-sale markdowns run through net revenues, offset below the line by a $2.48bn reserve release.

Sheet ROTE Driver Model
A2: KEY DRIVER — SUSTAINABLE ROTE -> JUSTIFIED PRICE / TANGIBLE BOOK
B3: A universal bank does not have a revenue multiple worth modelling: it has a book of equity and a return on it. Everything that matters for GS's valuation collapses into one number - the return on tangible common equity the franchise can sustain THROUGH a cycle - because price/tangible book is mechanically tied to it: P/TBV = (ROTE - g) / (COE - g). GS's 2Q26 annualised ROTE was 25.5%; its own published through-the-cycle target is 15-17%; FY2025 actual was 16.0%. The entire bull/bear argument is which of those numbers is the right anchor. Change the yellow cells to re-run.
A5: ANCHORS (observed)
B6: Tangible book value per share, 2Q26 ($) | D6: =Cover_TBVPS -> 336.61 | J6: Link to Cover
B7: Current price ($) | D7: =Cover_Price -> 1033.99 | J7: Link to Cover
B8: Current P / tangible book (x) | D8: =Cover_PTBV -> 3.0717745 | J8: Link to Cover
B9: 2Q26 annualised ROTE | D9: 0.255 | J9: 2Q26 earnings presentation
B10: 1H26 year-to-date ROTE | D10: 0.234 | J10: 2Q26 earnings presentation
B11: FY2025 ROTE | D11: 0.16 | J11: FY2025 earnings release
B12: FY2024 ROTE | D12: 0.135 | J12: FY2024 earnings release
B13: Management through-the-cycle ROTE target (low) | D13: 0.15 | J13: 1Q26 earnings call: 15-17% ROTE target
B14: Management through-the-cycle ROTE target (high) | D14: 0.17 | J14: 1Q26 earnings call
A16: BASE-CASE ASSUMPTIONS (the levers)
B17: Sustainable through-cycle ROTE | D17: 0.19 | J17: Judgment: above the 15-17% target, below the 25.5% spot rate
B18: Cost of equity (COE) | D18: 0.105 | J18: Judgment. NOT derived from a dated risk-free rate — see Sources gap note
B19: Long-run growth in tangible book per share (g) | D19: 0.04 | J19: Judgment; constrained by buybacks executed above tangible book (see below)
A21: OUTPUT — JUSTIFIED MULTIPLE AND PRICE
B22: Justified P / tangible book (x) | D22: =IF($D$19>=$D$18,"n/m",($D$17-$D$19)/($D$18-$D$19)) -> 2.3076923
B23: Implied share price on 2Q26 tangible book ($) | D23: =IFERROR($D$22*$D$6,"n/m") -> 776.79231
B24: Upside / (downside) vs. current price | D24: =IFERROR($D$23/$D$7-1,"-") -> -0.24874292
A26: REVERSE-ENGINEERED: WHAT ROTE DOES TODAY'S PRICE IMPLY?
B27: Market-implied sustainable ROTE at the base COE and g | D27: =$D$7/$D$6*($D$18-$D$19)+$D$19 -> 0.23966534
B28: ...vs. management's 15-17% through-cycle target (pp above midpoint) | D28: =D27-0.16 -> 0.07966534
B29: This is the single most important cell in the model. It says the market is not paying for a 16%-ROTE bank at all; at a 10.5% cost of equity it is paying for a bank that earns roughly 24% on tangible equity forever. Anyone underwriting GS at this price is, implicitly, making that claim.
A31: GRID 1 — IMPLIED SHARE PRICE: sustainable ROTE (rows) x cost of equity (columns)
B32: Sustainable ROTE \ Cost of equity | C32: 0.09 | D32: 0.095 | E32: 0.1 | F32: 0.105 | G32: 0.11 | H32: 0.12
B33: 0.14 | C33: =IF(C$32<=$D$19,"n/m",($B33-$D$19)/(C$32-$D$19)*$D$6) -> 673.22 | D33: =IF(D$32<=$D$19,"n/m",($B33-$D$19)/(D$32-$D$19)*$D$6) -> 612.01818 | E33: =IF(E$32<=$D$19,"n/m",($B33-$D$19)/(E$32-$D$19)*$D$6) -> 561.01667 | F33: =IF(F$32<=$D$19,"n/m",($B33-$D$19)/(F$32-$D$19)*$D$6) -> 517.86154 | G33: =IF(G$32<=$D$19,"n/m",($B33-$D$19)/(G$32-$D$19)*$D$6) -> 480.87143 | H33: =IF(H$32<=$D$19,"n/m",($B33-$D$19)/(H$32-$D$19)*$D$6) -> 420.7625
B34: 0.16 | C34: =IF(C$32<=$D$19,"n/m",($B34-$D$19)/(C$32-$D$19)*$D$6) -> 807.864 | D34: =IF(D$32<=$D$19,"n/m",($B34-$D$19)/(D$32-$D$19)*$D$6) -> 734.42182 | E34: =IF(E$32<=$D$19,"n/m",($B34-$D$19)/(E$32-$D$19)*$D$6) -> 673.22 | F34: =IF(F$32<=$D$19,"n/m",($B34-$D$19)/(F$32-$D$19)*$D$6) -> 621.43385 | G34: =IF(G$32<=$D$19,"n/m",($B34-$D$19)/(G$32-$D$19)*$D$6) -> 577.04571 | H34: =IF(H$32<=$D$19,"n/m",($B34-$D$19)/(H$32-$D$19)*$D$6) -> 504.915
B35: 0.18 | C35: =IF(C$32<=$D$19,"n/m",($B35-$D$19)/(C$32-$D$19)*$D$6) -> 942.508 | D35: =IF(D$32<=$D$19,"n/m",($B35-$D$19)/(D$32-$D$19)*$D$6) -> 856.82545 | E35: =IF(E$32<=$D$19,"n/m",($B35-$D$19)/(E$32-$D$19)*$D$6) -> 785.42333 | F35: =IF(F$32<=$D$19,"n/m",($B35-$D$19)/(F$32-$D$19)*$D$6) -> 725.00615 | G35: =IF(G$32<=$D$19,"n/m",($B35-$D$19)/(G$32-$D$19)*$D$6) -> 673.22 | H35: =IF(H$32<=$D$19,"n/m",($B35-$D$19)/(H$32-$D$19)*$D$6) -> 589.0675
B36: 0.2 | C36: =IF(C$32<=$D$19,"n/m",($B36-$D$19)/(C$32-$D$19)*$D$6) -> 1077.152 | D36: =IF(D$32<=$D$19,"n/m",($B36-$D$19)/(D$32-$D$19)*$D$6) -> 979.22909 | E36: =IF(E$32<=$D$19,"n/m",($B36-$D$19)/(E$32-$D$19)*$D$6) -> 897.62667 | F36: =IF(F$32<=$D$19,"n/m",($B36-$D$19)/(F$32-$D$19)*$D$6) -> 828.57846 | G36: =IF(G$32<=$D$19,"n/m",($B36-$D$19)/(G$32-$D$19)*$D$6) -> 769.39429 | H36: =IF(H$32<=$D$19,"n/m",($B36-$D$19)/(H$32-$D$19)*$D$6) -> 673.22
B37: 0.22 | C37: =IF(C$32<=$D$19,"n/m",($B37-$D$19)/(C$32-$D$19)*$D$6) -> 1211.796 | D37: =IF(D$32<=$D$19,"n/m",($B37-$D$19)/(D$32-$D$19)*$D$6) -> 1101.6327 | E37: =IF(E$32<=$D$19,"n/m",($B37-$D$19)/(E$32-$D$19)*$D$6) -> 1009.83 | F37: =IF(F$32<=$D$19,"n/m",($B37-$D$19)/(F$32-$D$19)*$D$6) -> 932.15077 | G37: =IF(G$32<=$D$19,"n/m",($B37-$D$19)/(G$32-$D$19)*$D$6) -> 865.56857 | H37: =IF(H$32<=$D$19,"n/m",($B37-$D$19)/(H$32-$D$19)*$D$6) -> 757.3725
B38: 0.24 | C38: =IF(C$32<=$D$19,"n/m",($B38-$D$19)/(C$32-$D$19)*$D$6) -> 1346.44 | D38: =IF(D$32<=$D$19,"n/m",($B38-$D$19)/(D$32-$D$19)*$D$6) -> 1224.0364 | E38: =IF(E$32<=$D$19,"n/m",($B38-$D$19)/(E$32-$D$19)*$D$6) -> 1122.0333 | F38: =IF(F$32<=$D$19,"n/m",($B38-$D$19)/(F$32-$D$19)*$D$6) -> 1035.7231 | G38: =IF(G$32<=$D$19,"n/m",($B38-$D$19)/(G$32-$D$19)*$D$6) -> 961.74286 | H38: =IF(H$32<=$D$19,"n/m",($B38-$D$19)/(H$32-$D$19)*$D$6) -> 841.525
B39: 0.26 | C39: =IF(C$32<=$D$19,"n/m",($B39-$D$19)/(C$32-$D$19)*$D$6) -> 1481.084 | D39: =IF(D$32<=$D$19,"n/m",($B39-$D$19)/(D$32-$D$19)*$D$6) -> 1346.44 | E39: =IF(E$32<=$D$19,"n/m",($B39-$D$19)/(E$32-$D$19)*$D$6) -> 1234.2367 | F39: =IF(F$32<=$D$19,"n/m",($B39-$D$19)/(F$32-$D$19)*$D$6) -> 1139.2954 | G39: =IF(G$32<=$D$19,"n/m",($B39-$D$19)/(G$32-$D$19)*$D$6) -> 1057.9171 | H39: =IF(H$32<=$D$19,"n/m",($B39-$D$19)/(H$32-$D$19)*$D$6) -> 925.6775
B40: Read the gradient: it runs far more steeply across the ROTE axis than across the cost-of-equity axis over these ranges. Sustainable profitability, not the discount rate, is what this valuation turns on. Trace where the current ~$1,034 price appears: it needs at least a 24% sustainable ROTE at a 10.5% cost of equity, or 26% at 11.0%. Nowhere in the 14-18% ROTE band - which spans management's own through-cycle target and the FY2024-FY2025 actuals - does any cost-of-equity assumption in this range produce today's price.
A42: GRID 2 — IMPLIED SHARE PRICE: sustainable ROTE (rows) x long-run TBV growth g (columns)
B43: Sustainable ROTE \ Long-run g | C43: 0.02 | D43: 0.03 | E43: 0.04 | F43: 0.05 | G43: 0.06
B44: 0.14 | C44: =IF(C$43>=$D$18,"n/m",($B44-C$43)/($D$18-C$43)*$D$6) -> 475.21412 | D44: =IF(D$43>=$D$18,"n/m",($B44-D$43)/($D$18-D$43)*$D$6) -> 493.69467 | E44: =IF(E$43>=$D$18,"n/m",($B44-E$43)/($D$18-E$43)*$D$6) -> 517.86154 | F44: =IF(F$43>=$D$18,"n/m",($B44-F$43)/($D$18-F$43)*$D$6) -> 550.81636 | G44: =IF(G$43>=$D$18,"n/m",($B44-G$43)/($D$18-G$43)*$D$6) -> 598.41778
B45: 0.16 | C45: =IF(C$43>=$D$18,"n/m",($B45-C$43)/($D$18-C$43)*$D$6) -> 554.41647 | D45: =IF(D$43>=$D$18,"n/m",($B45-D$43)/($D$18-D$43)*$D$6) -> 583.45733 | E45: =IF(E$43>=$D$18,"n/m",($B45-E$43)/($D$18-E$43)*$D$6) -> 621.43385 | F45: =IF(F$43>=$D$18,"n/m",($B45-F$43)/($D$18-F$43)*$D$6) -> 673.22 | G45: =IF(G$43>=$D$18,"n/m",($B45-G$43)/($D$18-G$43)*$D$6) -> 748.02222
B46: 0.18 | C46: =IF(C$43>=$D$18,"n/m",($B46-C$43)/($D$18-C$43)*$D$6) -> 633.61882 | D46: =IF(D$43>=$D$18,"n/m",($B46-D$43)/($D$18-D$43)*$D$6) -> 673.22 | E46: =IF(E$43>=$D$18,"n/m",($B46-E$43)/($D$18-E$43)*$D$6) -> 725.00615 | F46: =IF(F$43>=$D$18,"n/m",($B46-F$43)/($D$18-F$43)*$D$6) -> 795.62364 | G46: =IF(G$43>=$D$18,"n/m",($B46-G$43)/($D$18-G$43)*$D$6) -> 897.62667
B47: 0.2 | C47: =IF(C$43>=$D$18,"n/m",($B47-C$43)/($D$18-C$43)*$D$6) -> 712.82118 | D47: =IF(D$43>=$D$18,"n/m",($B47-D$43)/($D$18-D$43)*$D$6) -> 762.98267 | E47: =IF(E$43>=$D$18,"n/m",($B47-E$43)/($D$18-E$43)*$D$6) -> 828.57846 | F47: =IF(F$43>=$D$18,"n/m",($B47-F$43)/($D$18-F$43)*$D$6) -> 918.02727 | G47: =IF(G$43>=$D$18,"n/m",($B47-G$43)/($D$18-G$43)*$D$6) -> 1047.2311
...

Sheet Valuation
A2: PEER MULTIPLES — BANKS TRADE ON P/TBV AGAINST ROTE, NOT ON REVENUE MULTIPLES
B3: EV/Revenue and EV/EBITDA are not meaningful for a bank holding company: debt is raw material, not leverage, so enterprise value has no economic content. The meaningful pair is price/tangible book against return on tangible common equity. IMPORTANT: the as-of dates below differ by up to six weeks and could not be pulled same-day; several aggregators served visibly stale GS quotes (in the $780-$800 range) while researching this report. Treat the multiples as indicative, not precise.
B5: Company | C5: Price ($) | D5: TBVPS ($) | E5: P / TBV (x) | F5: Latest ROTE | G5: As-of date | H5: True comp?
B6: Goldman Sachs (GS) | C6: =Cover_Price -> 1033.99 | D6: =Cover_TBVPS -> 336.61 | E6: =C6/D6 -> 3.0717745 | F6: 0.255 | G6: 28-Aug-2026 | H6: subject
B7: Morgan Stanley (MS) | C7: 214.2 | D7: 53.18 | E7: =IFERROR(C7/D7,"-") -> 4.02783 | F7: 0.266 | G7: ~24-Aug-2026 | H7: Yes — closest comp
B8: JPMorgan Chase (JPM) | C8: 341.1 | D8: n/a | E8: 3.27 | F8: 0.23 | G8: 19-Jul-2026 | H8: Partial — deposit-led mix
B9: Bank of America (BAC) | C9: n/a | D9: n/a | E9: 2.14 | F9: 0.18 | G9: 14-Jul-2026 | H9: Reference only
B11: Capital Markets industry median P/TBV | E11: 1.35 | H11: GuruFocus, 754 Capital Markets companies
B12: Morgan Stanley 10-year median P/TBV | E12: 1.94 | H12: GuruFocus — shows how far the whole group has re-rated
B14: The finding that cuts against the driver model: on SPOT returns GS screens CHEAP within this group. It earns a 2Q26 ROTE within a point of Morgan Stanley's, and above JPMorgan's, yet trades at ~3.1x tangible book versus ~4.0x and ~3.3x. A defensible reason exists - GS's earnings are far more cyclical, with roughly three-quarters of revenue from Global Banking & Markets against Morgan Stanley's fee-based wealth franchise and JPMorgan's deposit base - so a lower multiple on the same spot return is not obviously mispricing. But it does mean the bear case rests on GS's returns normalising, not on the stock being expensive relative to its peers today.
A16: METHOD 2 — PEER P/TBV vs. ROTE REGRESSION (two-point fit, BAC to MS)
B17: Slope (P/TBV per 1pp of ROTE) | D17: =(E7-E9)/(F7-F9) -> 21.951512
B18: Intercept | D18: =E9-$D$17*F9 -> -1.8112721
B19: Fitted P/TBV at GS's SPOT 25.5% ROTE (x) | D19: =$D$18+$D$17*F6 -> 3.7863634
B20: GS actual P/TBV (x) | D20: =E6 -> 3.0717745
B21: Fitted on only two anchor points (BAC and MS), so this is a sanity check on relative positioning, not a statistical estimate. Its whole value is that it can be run at a NORMALISED ROTE rather than a spot one — which is how it reconciles with the Gordon model below.
A23: SCENARIO VALUATION — BOTH METHODS DRIVEN OFF ONE ASSUMPTION: SUSTAINABLE ROTE
C24: Bear | D24: Base | E24: Bull
B25: Sustainable through-cycle ROTE | C25: 0.15 | D25: 0.19 | E25: 0.24 | I25: Bear = bottom of management's own 15-17% target; Bull ~ 1H26 actual persists
B26: Cost of equity | C26: 0.115 | D26: 0.105 | E26: 0.095 | I26: Bear widens the discount rate as earnings look more cyclical
B27: Long-run growth in tangible book (g) | C27: 0.035 | D27: 0.04 | E27: 0.045
B28: 12-month forward TBVPS ($) | C28: =Fwd_TBVPS -> 348.2996 | D28: =Fwd_TBVPS -> 348.2996 | E28: =Fwd_TBVPS -> 348.2996 | I28: Link to the roll-forward on the ROTE Driver Model tab
B30: Method 1 — justified P/TBV (Gordon) (x) | C30: =IF(C27>=C26,"n/m",(C25-C27)/(C26-C27)) -> 1.4375 | D30: =IF(D27>=D26,"n/m",(D25-D27)/(D26-D27)) -> 2.3076923 | E30: =IF(E27>=E26,"n/m",(E25-E27)/(E26-E27)) -> 3.9
B31: Method 1 — implied share price ($) | C31: =IFERROR(C30*C28,"n/m") -> 500.68068 | D31: =IFERROR(D30*D28,"n/m") -> 803.76831 | E31: =IFERROR(E30*E28,"n/m") -> 1358.3684
B32: Method 2 — peer-regression P/TBV at scenario ROTE (x) | C32: =$D$18+$D$17*C25 -> 1.4814546 | D32: =$D$18+$D$17*D25 -> 2.3595151 | E32: =$D$18+$D$17*E25 -> 3.4570907
B33: Method 2 — implied share price ($) | C33: =C32*C28 -> 515.99006 | D33: =D32*D28 -> 821.81818 | E33: =E32*E28 -> 1204.1033
B35: Blended implied share price ($) | C35: =AVERAGE(C31,C33) -> 508.33537 | D35: =AVERAGE(D31,D33) -> 812.79324 | E35: =AVERAGE(E31,E33) -> 1281.2359 | I35: Simple average of the two methods
B36: Upside / (downside) to blended target | C36: =IFERROR(C35/Cover_Price-1,"-") -> -0.50837496 | D36: =IFERROR(D35/Cover_Price-1,"-") -> -0.21392543 | E36: =IFERROR(E35/Cover_Price-1,"-") -> 0.23911825
B38: Scenario probability weight | C38: 0.25 | D38: 0.5 | E38: 0.25 | I38: The model's own judgment, stated explicitly — not a consensus distribution
B39: Probability-weighted target ($) | D39: =SUMPRODUCT(C35:E35,C38:E38) -> 853.78943
B40: Upside / (downside) to weighted target | D40: =IFERROR(D39/Cover_Price-1,"-") -> -0.17427689
B42: How the two methods reconcile: run at GS's SPOT 25.5% ROTE, the peer regression implies roughly 3.8x tangible book and a price well above today's - GS looks cheap. Run at a NORMALISED 19% ROTE, the same regression implies about 2.4x, within a rounding error of the Gordon model's 2.3x. The two methods do not actually disagree about GS; they disagree about whether 2Q26 is the run-rate. That is the whole debate in one sentence, and no amount of modelling resolves it. Note also that the sell-side consensus target of ~$1,141 sits ABOVE the current price, meaning the street implicitly underwrites something close to the Bull column here — a genuine, material disagreement with this framework that the reader should weigh rather than dismiss.

Sheet Analyst Ratings
A2: SELL-SIDE COVERAGE SNAPSHOT
B4: Date | C4: Firm | D4: Rating | E4: Price target ($) | F4: Upside/(downside) | G4: Note
B5: 2026-06-30 | C5: Oppenheimer (Kotowski) | D5: Underperform | E5: n/a | F5: - | G5: Downgraded from Perform; flagged names running ahead of fundamentals
B6: 2026-07-14 | C6: JPMorgan | D6: Neutral | E6: 900 | F6: =IFERROR(E6/Cover_Price-1,"-") -> -0.12958539 | G6: Materially below the consensus range
B7: ~2026-08 | C7: Morgan Stanley | D7: Equal Weight | E7: 1021 | F7: =IFERROR(E7/Cover_Price-1,"-") -> -0.012562984 | G7: Target cut from $1,078
A10: CONSENSUS
B11: Number of analysts covering | C11: 25 | G11: stockanalysis.com / CleaRank both cite 25
B12: Consensus rating | C12: Hold | G12: stockanalysis.com. Other aggregators show 'Moderate Buy' — flagged
B13: Consensus price target ($) | C13: 1141.65 | G13: stockanalysis.com. CleaRank cites $1,150 across 25 analysts
B14: Implied upside/(downside) to consensus | C14: =IFERROR(C13/Cover_Price-1,"-") -> 0.10412093 | G14: Formula
B15: Lowest visible target ($) | C15: 900 | G15: JPMorgan
B16: Highest visible target in July range ($) | C16: 1073 | G16: Top of the $1,019-1,073 range cited mid-July
B18: The spread is the signal. Visible targets run from $900 (JPMorgan, Neutral) to a consensus of ~$1,142, a range of roughly 27% of the share price, and at least one house (Oppenheimer) carries an outright Underperform. That is a genuinely contested name, not a consensus long. Coverage counts and the consensus rating label itself differ across aggregators — see Sources.

Sheet Technical & Market
A2: PRICE LEVELS, TREND AND POSITIONING
B4: Metric | C4: Value | D4: Source / note
B5: Last price ($) | C5: =Cover_Price -> 1033.99 | D5: stockanalysis.com close 28-Aug-2026
B6: 50-day SMA ($) | C6: 1054.48 | D6: Financhill / CleaRank, mid-Aug-2026
B7: 50-day EMA ($) | C7: 1035.76 | D7: Financhill, mid-Aug-2026
B8: 200-day SMA ($) | C8: 930.29 | D8: Financhill / CleaRank (a second Financhill figure shows $931.83)
B9: Price vs. 50-day SMA | C9: =Cover_Price/C6-1 -> -0.019431378 | D9: Formula
B10: Price vs. 200-day SMA | C10: =Cover_Price/C8-1 -> 0.11147062 | D10: Formula
B11: RSI (14) | C11: 48 | D11: Financhill 48.75 / CleaRank 47.92 / ChartMill 59.74 — sources disagree
B12: MACD | C12: -4.13 | D12: Financhill, mid-Aug-2026
B13: Bollinger band (25) low ($) | C13: 1018.81 | D13: Financhill
B14: Bollinger band (25) high ($) | C14: 1091.57 | D14: Financhill
B15: 52-week high ($) | C15: 1125 | D15: heygotrade
B16: 52-week low ($) | C16: 691.3 | D16: heygotrade
B17: Position in 52-week range | C17: =(Cover_Price-C16)/(C15-C16) -> 0.79015448 | D17: Formula: (price - low) / (high - low)
B18: Trailing 12-month total return | C18: 0.5522 | D18: TradingEconomics as at 13-May-2026 — STALE, treat as directional only
B19: Implied volatility | C19: not obtained | D19: GAP — no dated IV reading found in public sources
B20: Put/call skew and open interest | C20: not obtained | D20: GAP — options positioning not available
B21: Short interest (% of float) | C21: not obtained | D21: GAP — no dated short-interest figure found
B22: Free float (mm) | C22: 289.53 | D22: StockTitan
B23: Insider activity | C23: net sellers | D23: Simply Wall St: insiders sold ~$108mm net over 12 months; David Viniar filed intent to sell 68k shares
B24: Average buyback price paid in 2Q26 ($) | C24: 975.61 | D24: Derived: $4.00bn / 4.1mm shares repurchased
B26: Structure: a golden cross is in place (50-day above 200-day) and price sits roughly 11% above the 200-day, so the primary uptrend is intact. But price is below the 50-day SMA with a negative MACD and a neutral RSI near 48 — a stock consolidating a very large advance, not one breaking out. The $1,125 post-earnings high from 14-Jul is the obvious resistance; the 200-day near $930 is the first structural support and sits ~10% below. Note that GS repurchased 4.1mm shares in 2Q26 at an average of roughly $976, i.e. the company itself was buying below where the stock trades today.

Sheet Catalyst Calendar
A2: HISTORICAL CATALYSTS
B3: Date | C3: Event | D3: Stock reaction / effect
B4: 2026-01-15 | C4: FY2025 results: net revenues $58.28bn, EPS $51.32, ROE 15.0%. Q4 revenue $13.45bn missed on $2.26bn of Apple Card markdowns; EPS beat on a $2.48bn reserve release. | D4: Fell ~1.9% pre-market to ~$914.78 despite the EPS beat
B5: 2026-03-19 | C5: US banking agencies propose the Basel III Endgame re-proposal, a revised G-SIB surcharge and a revised standardized approach; combined with eSLR reform this cuts G-SIB tier 1 requirements ~6.0% (~$60bn). | D5: Sector-wide capital-relief tailwind; Governor Barr dissented
B6: 2026-04-13 | C6: 1Q26 results: net revenues $17.23bn, EPS $17.55, ROE 19.8%, ROTE 21.3%; record GBM revenues of $12.7bn. | D6: Second-highest quarter in firm history at the time
B7: 2026-06-30 | C7: Oppenheimer downgrades GS from Perform to Underperform (also cut BAC and C). | D7: Explicit call that the names had run ahead of fundamentals
B8: 2026-07-14 | C8: 2Q26 results: record net revenues $20.34bn, record EPS $20.98, ROE 23.5%, ROTE 25.5%; EPS beat consensus by ~46%, revenue by ~26%; dividend raised 11% QoQ to $5.00. | D8: Rose ~7.7% to ~$1,126 — the 52-week high
B9: 2026-08-10 | C9: Sao Paulo civil police formally accuse two Goldman representatives of fraud in the Oncoclinicas tender-offer dispute. | D9: Headline legal risk; no financial quantification disclosed
B10: 2026-08-12 | C10: Agrees to acquire ETF provider NEOS Investments for up to ~$2.25-2.3bn — the latest in a run of asset-management bolt-ons (Industry Ventures, Innovator, LCN Capital). | D10: Adds fee-based AUS; also adds goodwill, which dilutes tangible book
B11: 2026-08-24 | C11: SEC subpoenas GS, JPM, C and BAC for records on prime-brokerage dealings with Situational Awareness, the AI-focused fund that fell from ~$45bn to ~$10bn in July at reported leverage up to 400%. | D11: No allegation of wrongdoing; investigation at earliest stage
A13: FORWARD CATALYSTS
B14: Expected | C14: Event | D14: Why it matters
B15: Sep 2026 | C15: Ex-dividend 1-Sep for the raised $5.00 quarterly dividend. | D15: Confirms the 25% YoY dividend step-up is being paid, not just declared
B16: Mid-Oct 2026 | C16: 3Q26 results (GS has reported mid-October in each of the last two years). | D16: The single biggest test: is the mid-20s ROTE a run-rate or a peak? Watch the investment-banking backlog, which management says is at a five-year high
B17: 2H 2026 | C17: Finalisation of the March 2026 capital proposals after the 90-day comment period; the Fed signalled stress-testing changes would be finalised 'well before the end of the year'. | D17: Lower required capital raises sustainable ROTE mechanically — the one lever that could validate the market's ~24% implied ROTE
B18: 2H 2026 / 2027 | C18: Completion of the Apple Card programme transition; the portfolio has been held for sale since 4Q25 and continues to generate markdowns through Platform Solutions. | D18: Removes a persistent negative revenue line and a source of quarter-to-quarter noise
B19: Ongoing | C19: Progress of the SEC inquiry into prime-brokerage exposure to Situational Awareness, and any wider supervisory review of AI-infrastructure lending. | D19: GS's equities financing (prime) revenue was a record in 2Q26; a regulatory tightening of leverage to concentrated AI funds would hit the fastest-growing revenue line
B20: Ongoing | C20: Closing and integration of NEOS, plus further asset-management bolt-ons. | D20: Shifts mix toward fee revenue — but each deal adds goodwill and suppresses tangible book growth
B21: Oct 2026 (reported) | C21: A potential Anthropic listing, cited in press coverage as targeting as early as October 2026. | D21: Reported, not confirmed — treat as an indicator of the ECM pipeline rather than a dated event

Sheet Sources & Notes
A2: SOURCES & DATA-QUALITY NOTES
B4: GENERAL
B5: Research compiled 30-Aug-2026 from public secondary sources: GS earnings releases and 8-K exhibits, the 2Q26 earnings results presentation, financial media, law-firm regulatory summaries and data aggregators. Not a Bloomberg or FactSet terminal pull. SEC EDGAR's XBRL API and FRED were unreachable from this environment (HTTP 403 at the egress proxy), so filing-level figures were taken from press-release text reproduced by EDGAR-mirroring sources rather than parsed from XBRL.
B7: COMPANY FILINGS AND PRESENTATIONS
B8: 2Q26 8-K, press release and earnings presentation (14-Jul-2026) — sec.gov/Archives/edgar/data/886982/000088698226000294/
B9: 1Q26 earnings results (13-Apr-2026) — sec.gov/Archives/edgar/data/886982/000088698226000096/a1q26gsearningsresults.htm
B10: FY2025 / 4Q25 earnings results (15-Jan-2026) — goldmansachs.com/pressroom/press-releases/2026/2026-01-15-q4-results
B11: 3Q25 earnings results and 10-Q (14-Oct-2025) — sec.gov/Archives/edgar/data/886982/000119312525238058/ and .../000088698225001411/gs-20250930.htm
B12: 2Q25 earnings results (16-Jul-2025) — sec.gov/Archives/edgar/data/886982/000119312525159560/d41877dex991.htm
B13: FY2024 / 4Q24 earnings results (15-Jan-2025) — sec.gov/Archives/edgar/data/886982/000119312525006554/d903229dex991.htm
B15: MARKET, VALUATION AND TECHNICAL DATA
B16: stockanalysis.com/stocks/gs/financials/ and /revenue/ — annual and segment revenue, TTM figures, P/E, close prices
B17: heygotrade.com/en/us-stock/gs/ — 52-week range; kraken.com/stocks/gs and cnn.com/markets/stocks/GS — recent quotes
... B42: 10. THE ANTHROPIC LISTING referenced in the forward catalysts is press speculation reported in coverage of the Situational Awareness episode, not a company-confirmed or scheduled event.
